Workbook

Sheet Start Here
B2: Client Reporting Dashboard
B3: The live view. Set four cells, get the whole picture.
B5: IDENTITY — these feed the titles on the Dashboard
B6: Client / brand name | C6: Northwind Supply Co.
B7: Prepared by | C7: Your Agency Name
B8: Currency code | C8: EGP
B10: HOW TO USE IT
B11: 1 | C11: Set the period
C12: Open KPI Calc. In row 4 put the period you're reporting. In row 5 put what you're comparing it to. Everything else moves.
B13: 2 | C13: Fill the business inputs
C14: KPI Calc, cells J5:J7 — COGS %, other variable cost %, and shipping per order. Without these the dashboard can show revenue but not profit.
B15: 3 | C15: Feed the data
C16: Paste into Fundamentals (account level) and Ad Data (ad level). Column order matters — don't insert or reorder columns. See 'Link the Automation' below to skip the pasting entirely.
B17: 4 | C17: Read the Dashboard
C18: That tab is the client-facing view. Tiles, platform split, funnel, and auto-written commentary you can paste straight into an email.
B19: 5 | C19: Check Health Check first
C20: Before anything goes to a client. It proves the ad-level data reconciles to the account-level data and flags impossible numbers.
B21: 6 | C21: Retune Benchmarks
C22: The status column is only as good as the thresholds. Put this client's own trailing 90-day numbers in after month two.
B24: LINK THE AUTOMATION — if you run the n8n Ads Reporting System
B25: Why this is optional | C25: This kit works entirely by hand. But if you already run the automated pipeline, the Raw Data sheet is the single source of truth — and the dashboard can read straight from it, so you never paste anything.
B26: Step 1 | C26: On the 'Fundamentals' tab, put your Raw Data sheet ID in cell N1. (It's the long string in the Raw sheet's URL between /d/ and /edit.) Then delete the sample rows 2 onward.
B27: Step 2 | C27: Paste this into Fundamentals!A2 — one formula, and the whole tab fills itself from the pipeline. It stacks the four raw tabs, keeps the columns this kit needs, and labels each platform. Approve the IMPORTRANGE access prompt the first time.
B28: Formula | C28: =LET( m, QUERY(IMPORTRANGE($N$1,"'Daily_Raw_Meta'!A2:P"),"select * where Col1 is not null",0), t, QUERY(IMPORTRANGE($N$1,"'Daily_Raw_TikTok'!A2:R"),"select * where Col1 is not null",0), VSTACK( {"Date","Platform","Spend","Impressions","Reach","Clicks","Landing Page Views","Add to Cart","Initiate Checkout","Purchases","Revenue"}, HSTACK(CHOOSECOLS(m,1),IF(CHOOSECOLS(m,1)<>"","Meta",""),CHOOSECOLS(m,2,3,4,7),IF(CHOOSECOLS(m,1)<>"","",""),CHOOSECOLS(m,9,10,11,12)), HSTACK(CHOOSECOLS(t,1),IF(CHOOSECOLS(t,1)<>"","TikTok",""),CHOOSECOLS(t,2,3,4,6),IF(CHOOSECOLS(t,1)<>"","",""),CHOOSECOLS(t,11,12,13,14)) ) )
B29: Note | C29: Google Sheets only — IMPORTRANGE does not exist in Excel, even Excel 365. In Excel, use Power Query against the sheet instead, or just paste. Use this formula on ONE line: Sheets accepts the line breaks, but if you paste from a PDF or chat window they can turn into characters that break it, so delete any line break that isn't a real newline.
B30: Column mapping | C30: Daily_Raw_Meta (A:P) gives Date, Spend, Impressions, Reach, Clicks, Adds_to_Cart, Initiate_Checkout, Purchases, Purchases_Value. Daily_Raw_TikTok (A:R) gives the same, one column apart. The formula maps them explicitly, so if your template ever gains a column, the mapping is the thing to re-check — not the whole dashboard.
B31: About landing page views | C31: Landing Page Views are left blank by the formula above, on purpose. Meta only reports LPV at AD level, not account level, and TikTok does not report it at all. If you want the Meta click-to-landing-page rate, put this in Fundamentals!G2 instead of the blank column — it sums Daily_Raw_Meta_Ads by date:
B32: LPV formula | C32: =ARRAYFORMULA(IF($A$2:$A="","", SUMIF(IMPORTRANGE($N$1,"'Daily_Raw_Meta_Ads'!A$2:A"),$A$2:$A, IMPORTRANGE($N$1,"'Daily_Raw_Meta_Ads'!N$2:N"))))
B33: If the numbers look wrong | C33: Two things cause almost every problem. (1) Column A must be a real date, not text — select it and check Format ▸ Number ▸ Date shows something sensible. If it is text, the date filters silently return zero. (2) You must approve the IMPORTRANGE access prompt — the first paste shows a #REF! and a button, and it only works after you click Allow. Run Health Check afterwards: it reports the row count and first/last date, which tells you immediately whether the link worked.

Sheet Fundamentals
A1: Date | B1: Platform | C1: Spend | D1: Impressions | E1: Reach | F1: Clicks | G1: Landing Page Views | H1: Add to Cart | I1: Initiate Checkout | J1: Purchases | K1: Revenue | M1: Raw Data sheet ID →
A2: 46218 | B2: Meta | C2: 3198.66 | D2: 53223 | E2: 20445 | F2: 952 | G2: 691 | H2: 50 | I2: 23 | J2: 18 | K2: 12332.42 | M2: Paste it here if you want to pull straight from the n8n pipeline (see 'Start Here'). Otherwise ignore this cell.
A3: 46218 | B3: TikTok | C3: 1545 | D3: 36031 | E3: 16462 | F3: 371 | H3: 22 | I3: 10 | J3: 7 | K3: 3991.45
A4: 46219 | B4: Meta | C4: 3161.31 | D4: 52769 | E4: 23334 | F4: 905 | G4: 621 | H4: 48 | I4: 21 | J4: 16 | K4: 11234.68
A5: 46219 | B5: TikTok | C5: 1455.37 | D5: 35728 | E5: 17252 | F5: 450 | H5: 29 | I5: 14 | J5: 9 | K5: 5543.14
A6: 46220 | B6: Meta | C6: 3507.27 | D6: 54057 | E6: 25800 | F6: 928 | G6: 671 | H6: 54 | I6: 26 | J6: 21 | K6: 13679.4
A7: 46220 | B7: TikTok | C7: 1670.76 | D7: 42798 | E7: 18687 | F7: 531 | H7: 30 | I7: 14 | J7: 9 | K7: 6079.58
A8: 46221 | B8: Meta | C8: 3469.98 | D8: 53247 | E8: 20932 | F8: 962 | G8: 682 | H8: 45 | I8: 23 | J8: 18 | K8: 11932.58
A9: 46221 | B9: TikTok | C9: 1881.23 | D9: 42912 | E9: 23740 | F9: 436 | H9: 27 | I9: 11 | J9: 7 | K9: 4353.79
A10: 46222 | B10: Meta | C10: 3490.23 | D10: 56059 | E10: 21828 | F10: 828 | G10: 638 | H10: 49 | I10: 24 | J10: 18 | K10: 12906.18
A11: 46222 | B11: TikTok | C11: 1438.27 | D11: 34811 | E11: 20074 | F11: 447 | H11: 31 | I11: 14 | J11: 9 | K11: 5741.4
A12: 46223 | B12: Meta | C12: 3327.28 | D12: 50478 | E12: 21302 | F12: 774 | G12: 581 | H12: 40 | I12: 19 | J12: 15 | K12: 10481.43
A13: 46223 | B13: TikTok | C13: 1385.47 | D13: 32374 | E13: 14480 | F13: 438 | H13: 27 | I13: 13 | J13: 9 | K13: 5385.92
A14: 46224 | B14: Meta | C14: 3189.3 | D14: 50159 | E14: 20267 | F14: 827 | G14: 678 | H14: 51 | I14: 26 | J14: 21 | K14: 14573.55
A15: 46224 | B15: TikTok | C15: 1355.02 | D15: 33451 | E15: 16531 | F15: 374 | H15: 22 | I15: 9 | J15: 6 | K15: 3450.55
A16: 46225 | B16: Meta | C16: 3074.11 | D16: 48118 | E16: 18479 | F16: 771 | G16: 564 | H16: 40 | I16: 18 | J16: 13 | K16: 9481.87
A17: 46225 | B17: TikTok | C17: 1498.14 | D17: 36403 | E17: 17644 | F17: 367 | H17: 25 | I17: 11 | J17: 7 | K17: 4111.35
A18: 46226 | B18: Meta | C18: 3215.18 | D18: 52963 | E18: 27000 | F18: 766 | G18: 576 | H18: 48 | I18: 23 | J18: 17 | K18: 12175.79
A19: 46226 | B19: TikTok | C19: 1403.65 | D19: 32751 | E19: 15745 | F19: 394 | H19: 25 | I19: 9 | J19: 6 | K19: 3491.39
A20: 46227 | B20: Meta | C20: 3675.47 | D20: 55762 | E20: 26192 | F20: 949 | G20: 769 | H20: 57 | I20: 28 | J20: 20 | K20: 14319.26
A21: 46227 | B21: TikTok | C21: 1495.99 | D21: 33779 | E21: 14786 | F21: 351 | H21: 23 | I21: 10 | J21: 6 | K21: 3651.54
A22: 46228 | B22: Meta | C22: 3646.96 | D22: 54385 | E22: 22375 | F22: 926 | G22: 744 | H22: 57 | I22: 26 | J22: 19 | K22: 13666.67
A23: 46228 | B23: TikTok | C23: 1544.85 | D23: 36993 | E23: 20898 | F23: 379 | H23: 24 | I23: 10 | J23: 6 | K23: 3866.24
A24: 46229 | B24: Meta | C24: 3461.35 | D24: 54820 | E24: 27958 | F24: 792 | G24: 542 | H24: 40 | I24: 21 | J24: 16 | K24: 11450.74
A25: 46229 | B25: TikTok | C25: 1733.41 | D25: 38489 | E25: 23783 | F25: 464 | H25: 26 | I25: 11 | J25: 8 | K25: 4753.57
A26: 46230 | B26: Meta | C26: 3331.86 | D26: 50662 | E26: 20941 | F26: 832 | G26: 674 | H26: 47 | I26: 24 | J26: 17 | K26: 11516.83
A27: 46230 | B27: TikTok | C27: 1573.27 | D27: 37813 | E27: 18304 | F27: 485 | H27: 31 | I27: 14 | J27: 9 | K27: 5534.42
A28: 46231 | B28: Meta | C28: 2979.4 | D28: 46179 | E28: 17212 | F28: 663 | G28: 541 | H28: 44 | I28: 22 | J28: 18 | K28: 12164.38
A29: 46231 | B29: TikTok | C29: 1334.14 | D29: 30506 | E29: 14601 | F29: 341 | H29: 19 | I29: 8 | J29: 5 | K29: 3463.92
A30: 46232 | B30: Meta | C30: 3128.57 | D30: 47720 | E30: 21499 | F30: 806 | G30: 566 | H30: 45 | I30: 20 | J30: 16 | K30: 11081.1
A31: 46232 | B31: TikTok | C31: 1545.54 | D31: 34385 | E31: 20407 | F31: 375 | H31: 21 | I31: 10 | J31: 7 | K31: 4016.92
A32: 46233 | B32: Meta | C32: 3072.57 | D32: 45306 | E32: 20983 | F32: 766 | G32: 572 | H32: 39 | I32: 20 | J32: 16 | K32: 11159.73
A33: 46233 | B33: TikTok | C33: 1556.7 | D33: 34572 | E33: 15315 | F33: 400 | H33: 23 | I33: 10 | J33: 7 | K33: 4545.96
A34: 46234 | B34: Meta | C34: 3466.35 | D34: 53668 | E34: 20616 | F34: 954 | G34: 681 | H34: 52 | I34: 26 | J34: 18 | K34: 13464.14
A35: 46234 | B35: TikTok | C35: 1627.14 | D35: 37462 | E35: 19128 | F35: 493 | H35: 28 | I35: 11 | J35: 8 | K35: 4911.4
A36: 46235 | B36: Meta | C36: 4103.75 | D36: 62170 | E36: 23302 | F36: 973 | G36: 740 | H36: 61 | I36: 26 | J36: 19 | K36: 13394.6
A37: 46235 | B37: TikTok | C37: 2019.59 | D37: 47163 | E37: 24555 | F37: 563 | H37: 38 | I37: 14 | J37: 9 | K37: 5371.32
A38: 46236 | B38: Meta | C38: 4118.93 | D38: 63306 | E38: 25071 | F38: 1151 | G38: 931 | H38: 75 | I38: 38 | J38: 28 | K38: 19131.76
A39: 46236 | B39: TikTok | C39: 1872.63 | D39: 42028 | E39: 22683 | F39: 560 | H39: 38 | I39: 17 | J39: 11 | K39: 6628.51
A40: 46237 | B40: Meta | C40: 3424.58 | D40: 50846 | E40: 20223 | F40: 832 | G40: 645 | H40: 50 | I40: 24 | J40: 19 | K40: 13586.02
...

Sheet Ad Data
A1: Date | B1: Platform | C1: Ad Name | D1: Campaign | E1: Ad Group / Ad Set | F1: Creative Key | G1: Spend | H1: Impressions | I1: Clicks | J1: Purchases | K1: Revenue
A2: 46218 | B2: Meta | C2: VID | Founder story | v4 | D2: Prospecting | Broad | EG | E2: UGC-Founder | F2: 883.12 | G2: 14694 | H2: 263 | I2: 6 | J2: 3941.98
A3: 46218 | B3: Meta | C3: STATIC | Bundle offer | v2 | D3: Prospecting | Broad | EG | E3: Static-Bundle | F3: 556.49 | G3: 9260 | H3: 166 | I3: 3 | J3: 2143.07
A4: 46218 | B4: Meta | C4: VID | Founder story | v3 | D4: Prospecting | Broad | EG | E4: UGC-Founder | F4: 487.31 | G4: 8108 | H4: 145 | I4: 2 | J4: 1323.36
A5: 46218 | B5: Meta | C5: VID | Review compilation | v1 | D5: Prospecting | Interest | EG | E5: UGC-Reviews | F5: 406.4 | G5: 6762 | H5: 121 | I5: 2 | J5: 1329.4
A6: 46218 | B6: Meta | C6: STATIC | Bundle offer | v1 | D6: Test | Broad | EG | E6: Static-Bundle | F6: 314.15 | G6: 5227 | H6: 93 | I6: 1 | J6: 713.03
A7: 46218 | B7: Meta | C7: STATIC | Discount 20% | v1 | D7: Retargeting | 7d IC | E7: Static-Discount | F7: 248.56 | G7: 4136 | H7: 74 | I7: 2 | J7: 1542.58
A8: 46218 | B8: Meta | C8: CAROUSEL | Best sellers | D8: Retargeting | 14d ATC | E8: Carousel-Bestsellers | F8: 157.26 | G8: 2617 | H8: 47 | I8: 2 | J8: 1338.99
A9: 46218 | B9: Meta | C9: VID | Founder story | v1 | D9: Prospecting | Broad | EG | E9: UGC-Founder | F9: 145.36 | G9: 2419 | H9: 43 | I9: 0 | J9: 0
A10: 46219 | B10: Meta | C10: VID | Founder story | v4 | D10: Prospecting | Broad | EG | E10: UGC-Founder | F10: 870.01 | G10: 14522 | H10: 249 | I10: 5 | J10: 3372.16
A11: 46219 | B11: Meta | C11: STATIC | Bundle offer | v2 | D11: Prospecting | Broad | EG | E11: Static-Bundle | F11: 633.69 | G11: 10578 | H11: 181 | I11: 3 | J11: 2011.77
A12: 46219 | B12: Meta | C12: VID | Founder story | v3 | D12: Prospecting | Broad | EG | E12: UGC-Founder | F12: 428.68 | G12: 7156 | H12: 123 | I12: 2 | J12: 1396.56
A13: 46219 | B13: Meta | C13: VID | Review compilation | v1 | D13: Prospecting | Interest | EG | E13: UGC-Reviews | F13: 406 | G13: 6777 | H13: 116 | I13: 2 | J13: 1544
... A1081: 46307 | B1081: TikTok | C1081: Spark ad | Creator A | D1081: Spark | Creator A | E1081: TT-Spark-CreatorA | F1081: 375.01 | G1081: 6736 | H1081: 77 | I1081: 1 | J1081: 590.04

Sheet KPI Calc
A1: KPI Calculator — live
A2: Every number recalculates from Fundamentals. Change the four date cells and the whole kit follows.
A3: All amounts in EGP. Change the currency label on 'Start Here' after you copy this file.
A4: Current period | B4: 46266 | C4: 46295 | I4: BUSINESS INPUTS
A5: Compare against | B5: 46235 | C5: 46265 | I5: COGS % of revenue | J5: 0.3
I6: Other variable cost % of revenue | J6: 0.06
A7: PERIOD RESULTS — current versus comparison | I7: Shipping & fulfilment per order | J7: 72
A8: Metric | B8: Current | C8: Compare | D8: Change | E8: Δ % | F8: Status | G8: How to read it | I8: Ask the client for these three. Everything about profit depends on them.
A9: Ad spend | B9: =SUMIFS(Fundamentals!$C$2:$C$6000,Fundamentals!$A$2:$A$6000,">="&$B$4,Fundamentals!$A$2:$A$6000,"<="&$C$4) | C9: =SUMIFS(Fundamentals!$C$2:$C$6000,Fundamentals!$A$2:$A$6000,">="&$B$5,Fundamentals!$A$2:$A$6000,"<="&$C$5) | D9: =B9-C9 | E9: =IFERROR(B9/C9-1,0) | G9: Media only — exclude your fee
A10: Impressions | B10: =SUMIFS(Fundamentals!$D$2:$D$6000,Fundamentals!$A$2:$A$6000,">="&$B$4,Fundamentals!$A$2:$A$6000,"<="&$C$4) | C10: =SUMIFS(Fundamentals!$D$2:$D$6000,Fundamentals!$A$2:$A$6000,">="&$B$5,Fundamentals!$A$2:$A$6000,"<="&$C$5) | D10: =B10-C10 | E10: =IFERROR(B10/C10-1,0) | G10: Volume of attention bought
A11: Reach (sum of daily) | B11: =SUMIFS(Fundamentals!$E$2:$E$6000,Fundamentals!$A$2:$A$6000,">="&$B$4,Fundamentals!$A$2:$A$6000,"<="&$C$4) | C11: =SUMIFS(Fundamentals!$E$2:$E$6000,Fundamentals!$A$2:$A$6000,">="&$B$5,Fundamentals!$A$2:$A$6000,"<="&$C$5) | D11: =B11-C11 | E11: =IFERROR(B11/C11-1,0) | G11: Indicative — daily reach does not deduplicate across days
A12: Clicks | B12: =SUMIFS(Fundamentals!$F$2:$F$6000,Fundamentals!$A$2:$A$6000,">="&$B$4,Fundamentals!$A$2:$A$6000,"<="&$C$4) | C12: =SUMIFS(Fundamentals!$F$2:$F$6000,Fundamentals!$A$2:$A$6000,">="&$B$5,Fundamentals!$A$2:$A$6000,"<="&$C$5) | D12: =B12-C12 | E12: =IFERROR(B12/C12-1,0) | G12: Use link / outbound clicks only
A13: Landing page views | B13: =SUMIFS(Fundamentals!$G$2:$G$6000,Fundamentals!$A$2:$A$6000,">="&$B$4,Fundamentals!$A$2:$A$6000,"<="&$C$4) | C13: =SUMIFS(Fundamentals!$G$2:$G$6000,Fundamentals!$A$2:$A$6000,">="&$B$5,Fundamentals!$A$2:$A$6000,"<="&$C$5) | D13: =B13-C13 | E13: =IFERROR(B13/C13-1,0) | G13: Meta only — TikTok does not report LPV
A14: Add to cart | B14: =SUMIFS(Fundamentals!$H$2:$H$6000,Fundamentals!$A$2:$A$6000,">="&$B$4,Fundamentals!$A$2:$A$6000,"<="&$C$4) | C14: =SUMIFS(Fundamentals!$H$2:$H$6000,Fundamentals!$A$2:$A$6000,">="&$B$5,Fundamentals!$A$2:$A$6000,"<="&$C$5) | D14: =B14-C14 | E14: =IFERROR(B14/C14-1,0) | G14: Cheap early intent
A15: Initiate checkout | B15: =SUMIFS(Fundamentals!$I$2:$I$6000,Fundamentals!$A$2:$A$6000,">="&$B$4,Fundamentals!$A$2:$A$6000,"<="&$C$4) | C15: =SUMIFS(Fundamentals!$I$2:$I$6000,Fundamentals!$A$2:$A$6000,">="&$B$5,Fundamentals!$A$2:$A$6000,"<="&$C$5) | D15: =B15-C15 | E15: =IFERROR(B15/C15-1,0) | G15: Last step before money moves
A16: Purchases | B16: =SUMIFS(Fundamentals!$J$2:$J$6000,Fundamentals!$A$2:$A$6000,">="&$B$4,Fundamentals!$A$2:$A$6000,"<="&$C$4) | C16: =SUMIFS(Fundamentals!$J$2:$J$6000,Fundamentals!$A$2:$A$6000,">="&$B$5,Fundamentals!$A$2:$A$6000,"<="&$C$5) | D16: =B16-C16 | E16: =IFERROR(B16/C16-1,0) | G16: Platform-attributed orders
A17: Revenue | B17: =SUMIFS(Fundamentals!$K$2:$K$6000,Fundamentals!$A$2:$A$6000,">="&$B$4,Fundamentals!$A$2:$A$6000,"<="&$C$4) | C17: =SUMIFS(Fundamentals!$K$2:$K$6000,Fundamentals!$A$2:$A$6000,">="&$B$5,Fundamentals!$A$2:$A$6000,"<="&$C$5) | D17: =B17-C17 | E17: =IFERROR(B17/C17-1,0) | G17: Platform purchase value, not bank revenue
A19: CPM | B19: =IFERROR(B9/B10*1000,0) | C19: =IFERROR(C9/C10*1000,0) | D19: =B19-C19 | E19: =IFERROR(B19/C19-1,0) | F19: =IFERROR(INDEX(Benchmarks!$G$7:$G$21,1),"—") | G19: Cost of 1,000 impressions
A20: CPC | B20: =IFERROR(B9/B12,0) | C20: =IFERROR(C9/C12,0) | D20: =B20-C20 | E20: =IFERROR(B20/C20-1,0) | F20: =IFERROR(INDEX(Benchmarks!$G$7:$G$21,2),"—") | G20: Cost of a link click
A21: CTR | B21: =IFERROR(B12/B10,0) | C21: =IFERROR(C12/C10,0) | D21: =B21-C21 | E21: =IFERROR(B21/C21-1,0) | F21: =IFERROR(INDEX(Benchmarks!$G$7:$G$21,3),"—") | G21: Creative hook strength
A22: Frequency | B22: =IFERROR(B10/B11,0) | C22: =IFERROR(C10/C11,0) | D22: =B22-C22 | E22: =IFERROR(B22/C22-1,0) | F22: =IFERROR(INDEX(Benchmarks!$G$7:$G$21,9),"—") | G22: Impressions per person. Above 3.5, refresh creative
A23: Click → Add to cart % | B23: =IFERROR(B14/B12,0) | C23: =IFERROR(C14/C12,0) | D23: =B23-C23 | E23: =IFERROR(B23/C23-1,0) | F23: =IFERROR(INDEX(Benchmarks!$G$7:$G$21,5),"—") | G23: Across both platforms
A24: Add to cart → Checkout % | B24: =IFERROR(B15/B14,0) | C24: =IFERROR(C15/C14,0) | D24: =B24-C24 | E24: =IFERROR(B24/C24-1,0) | F24: =IFERROR(INDEX(Benchmarks!$G$7:$G$21,6),"—") | G24: Shipping cost and fees show up here
A25: Checkout → Purchase % | B25: =IFERROR(B16/B15,0) | C25: =IFERROR(C16/C15,0) | D25: =B25-C25 | E25: =IFERROR(B25/C25-1,0) | F25: =IFERROR(INDEX(Benchmarks!$G$7:$G$21,7),"—") | G25: Payment options and trust
A26: Click → Purchase CVR % | B26: =IFERROR(B16/B12,0) | C26: =IFERROR(C16/C12,0) | D26: =B26-C26 | E26: =IFERROR(B26/C26-1,0) | F26: =IFERROR(INDEX(Benchmarks!$G$7:$G$21,8),"—") | G26: End-to-end site conversion on paid clicks
A27: Click → Landing page % (Meta) | B27: =IFERROR(SUMIFS(Fundamentals!$G$2:$G$6000,Fundamentals!$A$2:$A$6000,">="&$B$4,Fundamentals!$A$2:$A$6000,"<="&$C$4)/SUMIFS(Fundamentals!$F$2:$F$6000,Fundamentals!$A$2:$A$6000,">="&$B$4,Fundamentals!$A$2:$A$6000,"<="&$C$4,Fundamentals!$B$2:$B$6000,"Meta"),0) | C27: =IFERROR(SUMIFS(Fundamentals!$G$2:$G$6000,Fundamentals!$A$2:$A$6000,">="&$B$5,Fundamentals!$A$2:$A$6000,"<="&$C$5)/SUMIFS(Fundamentals!$F$2:$F$6000,Fundamentals!$A$2:$A$6000,">="&$B$5,Fundamentals!$A$2:$A$6000,"<="&$C$5,Fundamentals!$B$2:$B$6000,"Meta"),0) | D27: =B27-C27 | E27: =IFERROR(B27/C27-1,0) | F27: =IFERROR(INDEX(Benchmarks!$G$7:$G$21,4),"—") | G27: Page-speed diagnostic. Below 60% is a technical problem
A28: Cost per purchase | B28: =IFERROR(B9/B16,0) | C28: =IFERROR(C9/C16,0) | D28: =B28-C28 | E28: =IFERROR(B28/C28-1,0) | F28: ="—" | G28: Always read beside AOV
A29: AOV | B29: =IFERROR(B17/B16,0) | C29: =IFERROR(C17/C16,0) | D29: =B29-C29 | E29: =IFERROR(B29/C29-1,0) | F29: =IFERROR(INDEX(Benchmarks!$G$7:$G$21,10),"—") | G29: Average order value
A30: ROAS | B30: =IFERROR(B17/B9,0) | C30: =IFERROR(C17/C9,0) | D30: =B30-C30 | E30: =IFERROR(B30/C30-1,0) | F30: =IFERROR(INDEX(Benchmarks!$G$7:$G$21,12),"—") | G30: Meaningless without breakeven ROAS
A31: Revenue per 1,000 impressions | B31: =IFERROR(B17/B10*1000,0) | C31: =IFERROR(C17/C10*1000,0) | D31: =B31-C31 | E31: =IFERROR(B31/C31-1,0) | F31: =IFERROR(INDEX(Benchmarks!$G$7:$G$21,11),"—") | G31: Cleanest single measure of media efficiency
A33: Contribution margin % | B33: =IFERROR(1-$J$5-$J$6-$J$7/B29,0) | C33: =IFERROR(1-$J$5-$J$6-$J$7/C29,0) | D33: =B33-C33 | E33: =IFERROR(B33/C33-1,0) | F33: =IFERROR(INDEX(Benchmarks!$G$7:$G$21,15),"—") | G33: What's left from revenue to pay for ads
A34: Contribution | B34: =IFERROR(B17*B33,0) | C34: =IFERROR(C17*C33,0) | D34: =B34-C34 | E34: =IFERROR(B34/C34-1,0) | G34: Revenue minus all variable costs
A35: BREAKEVEN ROAS | B35: =IFERROR(1/B33,0) | C35: =IFERROR(1/C33,0) | D35: =B35-C35 | E35: =IFERROR(B35/C35-1,0) | F35: =IFERROR(INDEX(Benchmarks!$G$7:$G$21,13),"—") | G35: Below this, every sale loses money
A36: Profit after ad spend | B36: =IFERROR(B34-B9,0) | C36: =IFERROR(C34-C9,0) | D36: =B36-C36 | E36: =IFERROR(B36/C36-1,0) | G36: Contribution minus media
A37: POAS (profit on ad spend) | B37: =IFERROR(B36/B9,0) | C37: =IFERROR(C36/C9,0) | D37: =B37-C37 | E37: =IFERROR(B37/C37-1,0) | F37: =IFERROR(INDEX(Benchmarks!$G$7:$G$21,14),"—") | G37: Profit per unit of spend
A38: Spend as % of revenue | B38: =IFERROR(B9/B17,0) | C38: =IFERROR(C9/C17,0) | D38: =B38-C38 | E38: =IFERROR(B38/C38-1,0) | G38: Share of revenue going back into ads
A40: =IF(B16=0,"No purchases in this period — check the date cells and the platform attribution window.","Spend "&TEXT(ROUND(B9,0),"#,##0")&" → revenue "&TEXT(ROUND(B17,0),"#,##0")&" ("&ROUND(B30,2)&"x ROAS) against a breakeven of "&ROUND(B35,2)&"x. "&IF(B30>=B35,"Profitable","Below breakeven — the account is losing money at this margin")&" · profit after ad spend "&TEXT(ROUND(B36,0),"#,##0")&" · POAS "&ROUND(B37,2)&"x.")

Sheet Dashboard
A1: ='Start Here'!C6
A2: =TEXT('KPI Calc'!$B$4,"yyyy-mm-dd")&" → "&TEXT('KPI Calc'!$C$4,"yyyy-mm-dd")&" vs "&TEXT('KPI Calc'!$B$5,"yyyy-mm-dd")&" → "&TEXT('KPI Calc'!$C$5,"yyyy-mm-dd")
A3: ="Prepared by "&'Start Here'!C7&" · all amounts in EGP"
A5: AD SPEND | C5: REVENUE | E5: ROAS | G5: PROFIT AFTER AD SPEND
A6: ='KPI Calc'!B9 | C6: ='KPI Calc'!B17 | E6: ='KPI Calc'!B30 | G6: ='KPI Calc'!B36
A7: ="vs "&TEXT('KPI Calc'!C9,"#,##0")&" last period" | C7: ="vs "&TEXT('KPI Calc'!C17,"#,##0")&" last period" | E7: ="breakeven "&ROUND('KPI Calc'!B35,2)&"x" | G7: ="POAS "&ROUND('KPI Calc'!B37,2)&"x"
A9: PURCHASES | C9: AOV | E9: COST PER PURCHASE | G9: REVENUE / 1,000 IMPRESSIONS
A10: ='KPI Calc'!B16 | C10: ='KPI Calc'!B29 | E10: ='KPI Calc'!B28 | G10: ='KPI Calc'!B31
A11: ="vs "&TEXT('KPI Calc'!C16,"#,##0")&" last period" | C11: ="vs "&TEXT('KPI Calc'!C29,"#,##0")&" last period" | E11: ="contribution/order "&TEXT('KPI Calc'!B34/MAX(1,'KPI Calc'!B16),"#,##0") | G11: ="CPM "&TEXT('KPI Calc'!B19,"#,##0")
A13: WHERE THE BUDGET WENT
A14: Platform | B14: Spend | C14: Revenue | D14: ROAS | E14: Purchases | F14: Cost / purchase | G14: Share of spend
A15: Meta | B15: =SUMIFS(Fundamentals!$C$2:$C$6000,Fundamentals!$A$2:$A$6000,">="&$B$4,Fundamentals!$A$2:$A$6000,"<="&$C$4,Fundamentals!$B$2:$B$6000,"Meta") | C15: =SUMIFS(Fundamentals!$K$2:$K$6000,Fundamentals!$A$2:$A$6000,">="&$B$4,Fundamentals!$A$2:$A$6000,"<="&$C$4,Fundamentals!$B$2:$B$6000,"Meta") | D15: =IFERROR(C15/B15,0) | E15: =SUMIFS(Fundamentals!$J$2:$J$6000,Fundamentals!$A$2:$A$6000,">="&$B$4,Fundamentals!$A$2:$A$6000,"<="&$C$4,Fundamentals!$B$2:$B$6000,"Meta") | F15: =IFERROR(B15/E15,0) | G15: =IFERROR(B15/$B$17,0) | H15: =REPT("█",ROUND(14*IFERROR(B15/$B$17,0),0))
A16: TikTok | B16: =SUMIFS(Fundamentals!$C$2:$C$6000,Fundamentals!$A$2:$A$6000,">="&$B$4,Fundamentals!$A$2:$A$6000,"<="&$C$4,Fundamentals!$B$2:$B$6000,"TikTok") | C16: =SUMIFS(Fundamentals!$K$2:$K$6000,Fundamentals!$A$2:$A$6000,">="&$B$4,Fundamentals!$A$2:$A$6000,"<="&$C$4,Fundamentals!$B$2:$B$6000,"TikTok") | D16: =IFERROR(C16/B16,0) | E16: =SUMIFS(Fundamentals!$J$2:$J$6000,Fundamentals!$A$2:$A$6000,">="&$B$4,Fundamentals!$A$2:$A$6000,"<="&$C$4,Fundamentals!$B$2:$B$6000,"TikTok") | F16: =IFERROR(B16/E16,0) | G16: =IFERROR(B16/$B$17,0) | H16: =REPT("█",ROUND(14*IFERROR(B16/$B$17,0),0))
A17: Total | B17: =SUM(B15:B16) | C17: =SUM(C15:C16) | D17: =IFERROR(C17/B17,0) | E17: =SUM(E15:E16) | F17: =IFERROR(B17/E17,0) | G17: =IFERROR(B17/B17,0)
A19: THE FUNNEL — combined Meta + TikTok
A20: Step | B20: Count | C20: Step rate | D20: Target | E20: Status | F20: Bar
A21: Impressions | B21: ='KPI Calc'!B10
A22: Clicks | B22: ='KPI Calc'!B12 | C22: ='KPI Calc'!B21 | D22: =Benchmarks!$E$9 | E22: =IFERROR(INDEX(Benchmarks!$G$7:$G$21,3),"") | F22: =REPT("█",ROUND(20*IFERROR(C22,0),0))
A23: Add to cart | B23: ='KPI Calc'!B14 | C23: ='KPI Calc'!B23 | D23: =Benchmarks!$E$11 | E23: =IFERROR(INDEX(Benchmarks!$G$7:$G$21,5),"") | F23: =REPT("█",ROUND(20*IFERROR(C23,0),0))
A24: Initiate checkout | B24: ='KPI Calc'!B15 | C24: ='KPI Calc'!B24 | D24: =Benchmarks!$E$12 | E24: =IFERROR(INDEX(Benchmarks!$G$7:$G$21,6),"") | F24: =REPT("█",ROUND(20*IFERROR(C24,0),0))
A25: Purchases | B25: ='KPI Calc'!B16 | C25: ='KPI Calc'!B25 | D25: =Benchmarks!$E$13 | E25: =IFERROR(INDEX(Benchmarks!$G$7:$G$21,7),"") | F25: =REPT("█",ROUND(20*IFERROR(C25,0),0))
A26: Meta click → landing page | B26: =SUMIFS(Fundamentals!$G$2:$G$6000,Fundamentals!$A$2:$A$6000,">="&$B$4,Fundamentals!$A$2:$A$6000,"<="&$C$4) | C26: ='KPI Calc'!B27 | D26: =Benchmarks!$E$10 | E26: =IFERROR(INDEX(Benchmarks!$G$7:$G$21,4),"") | F26: =REPT("█",ROUND(20*IFERROR(C26,0),0)) | G26: Meta only — TikTok doesn't report landing page views
A28: WHAT TO SAY — generated from this period's numbers. Edit before you send.
A29: ="Headline: we spent "&TEXT(ROUND('KPI Calc'!B9,0),"#,##0")&" and returned "&TEXT(ROUND('KPI Calc'!B17,0),"#,##0")&" ("&ROUND('KPI Calc'!B30,2)&"x). "&IF('KPI Calc'!B30>='KPI Calc'!B35,"That is above the "&ROUND('KPI Calc'!B35,2)&"x breakeven, so media paid for itself this period.","That is below the "&ROUND('KPI Calc'!B35,2)&"x breakeven — media did not pay for itself this period and we need to talk about that directly.")
A30: ="Movement: spend "&IF('KPI Calc'!E9>=0,"up","down")&" "&TEXT(ABS('KPI Calc'!E9),"0%")&" while revenue "&IF('KPI Calc'!E17>=0,"rose","fell")&" "&TEXT(ABS('KPI Calc'!E17),"0%")&", so ROAS "&IF('KPI Calc'!B30>='KPI Calc'!C30,"improved","slipped")&" from "&ROUND('KPI Calc'!C30,2)&"x to "&ROUND('KPI Calc'!B30,2)&"x. Costs per thousand impressions went from "&TEXT(ROUND('KPI Calc'!C19,0),"#,##0")&" to "&TEXT(ROUND('KPI Calc'!B19,0),"#,##0")&".",
A31: ="Where the money went: "&TEXT('Dashboard'!G15,"0%")&" of budget on Meta returning "&ROUND('Dashboard'!D15,2)&"x, and "&TEXT('Dashboard'!G16,"0%")&" on TikTok returning "&ROUND('Dashboard'!D16,2)&"x. "&IF('Dashboard'!D15>'Dashboard'!D16,"Meta is the more efficient channel this period.","TikTok is the more efficient channel this period.")
A32: ="Efficiency read: CPM "&TEXT(ROUND('KPI Calc'!B19,0),"#,##0")&", CTR "&TEXT('KPI Calc'!B21,"0.00%")&", click-to-purchase "&TEXT('KPI Calc'!B26,"0.00%")&", AOV "&TEXT(ROUND('KPI Calc'!B29,0),"#,##0")&". Frequency is "&ROUND('KPI Calc'!B22,2)&", "&IF('KPI Calc'!B22>3.5,"which is high enough that creative fatigue is now a budget risk — fresh assets before we scale.","which leaves room to add budget without hitting fatigue.")
A33: ="Cost per purchase is "&TEXT(ROUND('KPI Calc'!B28,0),"#,##0")&" against an AOV of "&TEXT(ROUND('KPI Calc'!B29,0),"#,##0")&". At a "&TEXT('KPI Calc'!B33,"0.0%")&" contribution margin, breakeven ROAS is "&ROUND('KPI Calc'!B35,2)&"x, and headroom before we hit it is roughly "&TEXT(ROUND(MAX(0,'KPI Calc'!B17*'KPI Calc'!B33-'KPI Calc'!B9),0),"#,##0")&" more in spend at today's efficiency.",

Sheet Ad Performance
A1: Ad Performance
A2: Ranked by spend. One row per ad name — edit column A when you paste your own data.
A3: All amounts in EGP. Change the currency label on 'Start Here' after you copy this file.
A5: Ad Name | B5: Platform | C5: Campaign | D5: Creative Key | E5: Spend | F5: Impressions | G5: Clicks | H5: CTR | I5: Purchases | J5: Revenue | K5: ROAS | L5: Cost / purchase | M5: AOV | N5: Verdict
A6: VID | Founder story | v4 | B6: Meta | C6: Prospecting | Broad | EG | D6: UGC-Founder | E6: =SUMIFS('Ad Data'!$G$2:$G$6000,'Ad Data'!$C$2:$C$6000,$A6,'Ad Data'!$A$2:$A$6000,">="&'KPI Calc'!$B$4,'Ad Data'!$A$2:$A$6000,"<="&'KPI Calc'!$C$4) | F6: =SUMIFS('Ad Data'!$H$2:$H$6000,'Ad Data'!$C$2:$C$6000,$A6,'Ad Data'!$A$2:$A$6000,">="&'KPI Calc'!$B$4,'Ad Data'!$A$2:$A$6000,"<="&'KPI Calc'!$C$4) | G6: =SUMIFS('Ad Data'!$I$2:$I$6000,'Ad Data'!$C$2:$C$6000,$A6,'Ad Data'!$A$2:$A$6000,">="&'KPI Calc'!$B$4,'Ad Data'!$A$2:$A$6000,"<="&'KPI Calc'!$C$4) | H6: =IFERROR(G6/F6,0) | I6: =SUMIFS('Ad Data'!$J$2:$J$6000,'Ad Data'!$C$2:$C$6000,$A6,'Ad Data'!$A$2:$A$6000,">="&'KPI Calc'!$B$4,'Ad Data'!$A$2:$A$6000,"<="&'KPI Calc'!$C$4) | J6: =SUMIFS('Ad Data'!$K$2:$K$6000,'Ad Data'!$C$2:$C$6000,$A6,'Ad Data'!$A$2:$A$6000,">="&'KPI Calc'!$B$4,'Ad Data'!$A$2:$A$6000,"<="&'KPI Calc'!$C$4) | K6: =IFERROR(J6/E6,0) | L6: =IFERROR(E6/I6,0) | M6: =IFERROR(J6/I6,0) | N6: =IF(E6=0,"No spend in period",IF(K6>=MAX('KPI Calc'!$B$35*1.3,0.01),"Scale — put more budget here",IF(K6>='KPI Calc'!$B$35,"Working — maintain and refresh creative","Below breakeven — fix the page or cut it")))
A7: STATIC | Bundle offer | v2 | B7: Meta | C7: Prospecting | Broad | EG | D7: Static-Bundle | E7: =SUMIFS('Ad Data'!$G$2:$G$6000,'Ad Data'!$C$2:$C$6000,$A7,'Ad Data'!$A$2:$A$6000,">="&'KPI Calc'!$B$4,'Ad Data'!$A$2:$A$6000,"<="&'KPI Calc'!$C$4) | F7: =SUMIFS('Ad Data'!$H$2:$H$6000,'Ad Data'!$C$2:$C$6000,$A7,'Ad Data'!$A$2:$A$6000,">="&'KPI Calc'!$B$4,'Ad Data'!$A$2:$A$6000,"<="&'KPI Calc'!$C$4) | G7: =SUMIFS('Ad Data'!$I$2:$I$6000,'Ad Data'!$C$2:$C$6000,$A7,'Ad Data'!$A$2:$A$6000,">="&'KPI Calc'!$B$4,'Ad Data'!$A$2:$A$6000,"<="&'KPI Calc'!$C$4) | H7: =IFERROR(G7/F7,0) | I7: =SUMIFS('Ad Data'!$J$2:$J$6000,'Ad Data'!$C$2:$C$6000,$A7,'Ad Data'!$A$2:$A$6000,">="&'KPI Calc'!$B$4,'Ad Data'!$A$2:$A$6000,"<="&'KPI Calc'!$C$4) | J7: =SUMIFS('Ad Data'!$K$2:$K$6000,'Ad Data'!$C$2:$C$6000,$A7,'Ad Data'!$A$2:$A$6000,">="&'KPI Calc'!$B$4,'Ad Data'!$A$2:$A$6000,"<="&'KPI Calc'!$C$4) | K7: =IFERROR(J7/E7,0) | L7: =IFERROR(E7/I7,0) | M7: =IFERROR(J7/I7,0) | N7: =IF(E7=0,"No spend in period",IF(K7>=MAX('KPI Calc'!$B$35*1.3,0.01),"Scale — put more budget here",IF(K7>='KPI Calc'!$B$35,"Working — maintain and refresh creative","Below breakeven — fix the page or cut it")))
A8: VID | Founder story | v3 | B8: Meta | C8: Prospecting | Broad | EG | D8: UGC-Founder | E8: =SUMIFS('Ad Data'!$G$2:$G$6000,'Ad Data'!$C$2:$C$6000,$A8,'Ad Data'!$A$2:$A$6000,">="&'KPI Calc'!$B$4,'Ad Data'!$A$2:$A$6000,"<="&'KPI Calc'!$C$4) | F8: =SUMIFS('Ad Data'!$H$2:$H$6000,'Ad Data'!$C$2:$C$6000,$A8,'Ad Data'!$A$2:$A$6000,">="&'KPI Calc'!$B$4,'Ad Data'!$A$2:$A$6000,"<="&'KPI Calc'!$C$4) | G8: =SUMIFS('Ad Data'!$I$2:$I$6000,'Ad Data'!$C$2:$C$6000,$A8,'Ad Data'!$A$2:$A$6000,">="&'KPI Calc'!$B$4,'Ad Data'!$A$2:$A$6000,"<="&'KPI Calc'!$C$4) | H8: =IFERROR(G8/F8,0) | I8: =SUMIFS('Ad Data'!$J$2:$J$6000,'Ad Data'!$C$2:$C$6000,$A8,'Ad Data'!$A$2:$A$6000,">="&'KPI Calc'!$B$4,'Ad Data'!$A$2:$A$6000,"<="&'KPI Calc'!$C$4) | J8: =SUMIFS('Ad Data'!$K$2:$K$6000,'Ad Data'!$C$2:$C$6000,$A8,'Ad Data'!$A$2:$A$6000,">="&'KPI Calc'!$B$4,'Ad Data'!$A$2:$A$6000,"<="&'KPI Calc'!$C$4) | K8: =IFERROR(J8/E8,0) | L8: =IFERROR(E8/I8,0) | M8: =IFERROR(J8/I8,0) | N8: =IF(E8=0,"No spend in period",IF(K8>=MAX('KPI Calc'!$B$35*1.3,0.01),"Scale — put more budget here",IF(K8>='KPI Calc'!$B$35,"Working — maintain and refresh creative","Below breakeven — fix the page or cut it")))
A9: VID | Review compilation | v1 | B9: Meta | C9: Prospecting | Interest | EG | D9: UGC-Reviews | E9: =SUMIFS('Ad Data'!$G$2:$G$6000,'Ad Data'!$C$2:$C$6000,$A9,'Ad Data'!$A$2:$A$6000,">="&'KPI Calc'!$B$4,'Ad Data'!$A$2:$A$6000,"<="&'KPI Calc'!$C$4) | F9: =SUMIFS('Ad Data'!$H$2:$H$6000,'Ad Data'!$C$2:$C$6000,$A9,'Ad Data'!$A$2:$A$6000,">="&'KPI Calc'!$B$4,'Ad Data'!$A$2:$A$6000,"<="&'KPI Calc'!$C$4) | G9: =SUMIFS('Ad Data'!$I$2:$I$6000,'Ad Data'!$C$2:$C$6000,$A9,'Ad Data'!$A$2:$A$6000,">="&'KPI Calc'!$B$4,'Ad Data'!$A$2:$A$6000,"<="&'KPI Calc'!$C$4) | H9: =IFERROR(G9/F9,0) | I9: =SUMIFS('Ad Data'!$J$2:$J$6000,'Ad Data'!$C$2:$C$6000,$A9,'Ad Data'!$A$2:$A$6000,">="&'KPI Calc'!$B$4,'Ad Data'!$A$2:$A$6000,"<="&'KPI Calc'!$C$4) | J9: =SUMIFS('Ad Data'!$K$2:$K$6000,'Ad Data'!$C$2:$C$6000,$A9,'Ad Data'!$A$2:$A$6000,">="&'KPI Calc'!$B$4,'Ad Data'!$A$2:$A$6000,"<="&'KPI Calc'!$C$4) | K9: =IFERROR(J9/E9,0) | L9: =IFERROR(E9/I9,0) | M9: =IFERROR(J9/I9,0) | N9: =IF(E9=0,"No spend in period",IF(K9>=MAX('KPI Calc'!$B$35*1.3,0.01),"Scale — put more budget here",IF(K9>='KPI Calc'!$B$35,"Working — maintain and refresh creative","Below breakeven — fix the page or cut it")))
A10: STATIC | Bundle offer | v1 | B10: Meta | C10: Test | Broad | EG | D10: Static-Bundle | E10: =SUMIFS('Ad Data'!$G$2:$G$6000,'Ad Data'!$C$2:$C$6000,$A10,'Ad Data'!$A$2:$A$6000,">="&'KPI Calc'!$B$4,'Ad Data'!$A$2:$A$6000,"<="&'KPI Calc'!$C$4) | F10: =SUMIFS('Ad Data'!$H$2:$H$6000,'Ad Data'!$C$2:$C$6000,$A10,'Ad Data'!$A$2:$A$6000,">="&'KPI Calc'!$B$4,'Ad Data'!$A$2:$A$6000,"<="&'KPI Calc'!$C$4) | G10: =SUMIFS('Ad Data'!$I$2:$I$6000,'Ad Data'!$C$2:$C$6000,$A10,'Ad Data'!$A$2:$A$6000,">="&'KPI Calc'!$B$4,'Ad Data'!$A$2:$A$6000,"<="&'KPI Calc'!$C$4) | H10: =IFERROR(G10/F10,0) | I10: =SUMIFS('Ad Data'!$J$2:$J$6000,'Ad Data'!$C$2:$C$6000,$A10,'Ad Data'!$A$2:$A$6000,">="&'KPI Calc'!$B$4,'Ad Data'!$A$2:$A$6000,"<="&'KPI Calc'!$C$4) | J10: =SUMIFS('Ad Data'!$K$2:$K$6000,'Ad Data'!$C$2:$C$6000,$A10,'Ad Data'!$A$2:$A$6000,">="&'KPI Calc'!$B$4,'Ad Data'!$A$2:$A$6000,"<="&'KPI Calc'!$C$4) | K10: =IFERROR(J10/E10,0) | L10: =IFERROR(E10/I10,0) | M10: =IFERROR(J10/I10,0) | N10: =IF(E10=0,"No spend in period",IF(K10>=MAX('KPI Calc'!$B$35*1.3,0.01),"Scale — put more budget here",IF(K10>='KPI Calc'!$B$35,"Working — maintain and refresh creative","Below breakeven — fix the page or cut it")))
A11: STATIC | Discount 20% | v1 | B11: Meta | C11: Retargeting | 7d IC | D11: Static-Discount | E11: =SUMIFS('Ad Data'!$G$2:$G$6000,'Ad Data'!$C$2:$C$6000,$A11,'Ad Data'!$A$2:$A$6000,">="&'KPI Calc'!$B$4,'Ad Data'!$A$2:$A$6000,"<="&'KPI Calc'!$C$4) | F11: =SUMIFS('Ad Data'!$H$2:$H$6000,'Ad Data'!$C$2:$C$6000,$A11,'Ad Data'!$A$2:$A$6000,">="&'KPI Calc'!$B$4,'Ad Data'!$A$2:$A$6000,"<="&'KPI Calc'!$C$4) | G11: =SUMIFS('Ad Data'!$I$2:$I$6000,'Ad Data'!$C$2:$C$6000,$A11,'Ad Data'!$A$2:$A$6000,">="&'KPI Calc'!$B$4,'Ad Data'!$A$2:$A$6000,"<="&'KPI Calc'!$C$4) | H11: =IFERROR(G11/F11,0) | I11: =SUMIFS('Ad Data'!$J$2:$J$6000,'Ad Data'!$C$2:$C$6000,$A11,'Ad Data'!$A$2:$A$6000,">="&'KPI Calc'!$B$4,'Ad Data'!$A$2:$A$6000,"<="&'KPI Calc'!$C$4) | J11: =SUMIFS('Ad Data'!$K$2:$K$6000,'Ad Data'!$C$2:$C$6000,$A11,'Ad Data'!$A$2:$A$6000,">="&'KPI Calc'!$B$4,'Ad Data'!$A$2:$A$6000,"<="&'KPI Calc'!$C$4) | K11: =IFERROR(J11/E11,0) | L11: =IFERROR(E11/I11,0) | M11: =IFERROR(J11/I11,0) | N11: =IF(E11=0,"No spend in period",IF(K11>=MAX('KPI Calc'!$B$35*1.3,0.01),"Scale — put more budget here",IF(K11>='KPI Calc'!$B$35,"Working — maintain and refresh creative","Below breakeven — fix the page or cut it")))
A12: CAROUSEL | Best sellers | B12: Meta | C12: Retargeting | 14d ATC | D12: Carousel-Bestsellers | E12: =SUMIFS('Ad Data'!$G$2:$G$6000,'Ad Data'!$C$2:$C$6000,$A12,'Ad Data'!$A$2:$A$6000,">="&'KPI Calc'!$B$4,'Ad Data'!$A$2:$A$6000,"<="&'KPI Calc'!$C$4) | F12: =SUMIFS('Ad Data'!$H$2:$H$6000,'Ad Data'!$C$2:$C$6000,$A12,'Ad Data'!$A$2:$A$6000,">="&'KPI Calc'!$B$4,'Ad Data'!$A$2:$A$6000,"<="&'KPI Calc'!$C$4) | G12: =SUMIFS('Ad Data'!$I$2:$I$6000,'Ad Data'!$C$2:$C$6000,$A12,'Ad Data'!$A$2:$A$6000,">="&'KPI Calc'!$B$4,'Ad Data'!$A$2:$A$6000,"<="&'KPI Calc'!$C$4) | H12: =IFERROR(G12/F12,0) | I12: =SUMIFS('Ad Data'!$J$2:$J$6000,'Ad Data'!$C$2:$C$6000,$A12,'Ad Data'!$A$2:$A$6000,">="&'KPI Calc'!$B$4,'Ad Data'!$A$2:$A$6000,"<="&'KPI Calc'!$C$4) | J12: =SUMIFS('Ad Data'!$K$2:$K$6000,'Ad Data'!$C$2:$C$6000,$A12,'Ad Data'!$A$2:$A$6000,">="&'KPI Calc'!$B$4,'Ad Data'!$A$2:$A$6000,"<="&'KPI Calc'!$C$4) | K12: =IFERROR(J12/E12,0) | L12: =IFERROR(E12/I12,0) | M12: =IFERROR(J12/I12,0) | N12: =IF(E12=0,"No spend in period",IF(K12>=MAX('KPI Calc'!$B$35*1.3,0.01),"Scale — put more budget here",IF(K12>='KPI Calc'!$B$35,"Working — maintain and refresh creative","Below breakeven — fix the page or cut it")))
A13: VID | Founder story | v1 | B13: Meta | C13: Prospecting | Broad | EG | D13: UGC-Founder | E13: =SUMIFS('Ad Data'!$G$2:$G$6000,'Ad Data'!$C$2:$C$6000,$A13,'Ad Data'!$A$2:$A$6000,">="&'KPI Calc'!$B$4,'Ad Data'!$A$2:$A$6000,"<="&'KPI Calc'!$C$4) | F13: =SUMIFS('Ad Data'!$H$2:$H$6000,'Ad Data'!$C$2:$C$6000,$A13,'Ad Data'!$A$2:$A$6000,">="&'KPI Calc'!$B$4,'Ad Data'!$A$2:$A$6000,"<="&'KPI Calc'!$C$4) | G13: =SUMIFS('Ad Data'!$I$2:$I$6000,'Ad Data'!$C$2:$C$6000,$A13,'Ad Data'!$A$2:$A$6000,">="&'KPI Calc'!$B$4,'Ad Data'!$A$2:$A$6000,"<="&'KPI Calc'!$C$4) | H13: =IFERROR(G13/F13,0) | I13: =SUMIFS('Ad Data'!$J$2:$J$6000,'Ad Data'!$C$2:$C$6000,$A13,'Ad Data'!$A$2:$A$6000,">="&'KPI Calc'!$B$4,'Ad Data'!$A$2:$A$6000,"<="&'KPI Calc'!$C$4) | J13: =SUMIFS('Ad Data'!$K$2:$K$6000,'Ad Data'!$C$2:$C$6000,$A13,'Ad Data'!$A$2:$A$6000,">="&'KPI Calc'!$B$4,'Ad Data'!$A$2:$A$6000,"<="&'KPI Calc'!$C$4) | K13: =IFERROR(J13/E13,0) | L13: =IFERROR(E13/I13,0) | M13: =IFERROR(J13/I13,0) | N13: =IF(E13=0,"No spend in period",IF(K13>=MAX('KPI Calc'!$B$35*1.3,0.01),"Scale — put more budget here",IF(K13>='KPI Calc'!$B$35,"Working — maintain and refresh creative","Below breakeven — fix the page or cut it")))
A14: UGC | Problem-solution | v2 | B14: TikTok | C14: Prospecting | Broad | EG | D14: TT-UGC-ProbSol | E14: =SUMIFS('Ad Data'!$G$2:$G$6000,'Ad Data'!$C$2:$C$6000,$A14,'Ad Data'!$A$2:$A$6000,">="&'KPI Calc'!$B$4,'Ad Data'!$A$2:$A$6000,"<="&'KPI Calc'!$C$4) | F14: =SUMIFS('Ad Data'!$H$2:$H$6000,'Ad Data'!$C$2:$C$6000,$A14,'Ad Data'!$A$2:$A$6000,">="&'KPI Calc'!$B$4,'Ad Data'!$A$2:$A$6000,"<="&'KPI Calc'!$C$4) | G14: =SUMIFS('Ad Data'!$I$2:$I$6000,'Ad Data'!$C$2:$C$6000,$A14,'Ad Data'!$A$2:$A$6000,">="&'KPI Calc'!$B$4,'Ad Data'!$A$2:$A$6000,"<="&'KPI Calc'!$C$4) | H14: =IFERROR(G14/F14,0) | I14: =SUMIFS('Ad Data'!$J$2:$J$6000,'Ad Data'!$C$2:$C$6000,$A14,'Ad Data'!$A$2:$A$6000,">="&'KPI Calc'!$B$4,'Ad Data'!$A$2:$A$6000,"<="&'KPI Calc'!$C$4) | J14: =SUMIFS('Ad Data'!$K$2:$K$6000,'Ad Data'!$C$2:$C$6000,$A14,'Ad Data'!$A$2:$A$6000,">="&'KPI Calc'!$B$4,'Ad Data'!$A$2:$A$6000,"<="&'KPI Calc'!$C$4) | K14: =IFERROR(J14/E14,0) | L14: =IFERROR(E14/I14,0) | M14: =IFERROR(J14/I14,0) | N14: =IF(E14=0,"No spend in period",IF(K14>=MAX('KPI Calc'!$B$35*1.3,0.01),"Scale — put more budget here",IF(K14>='KPI Calc'!$B$35,"Working — maintain and refresh creative","Below breakeven — fix the page or cut it")))
A15: UGC | Trend audio | v1 | B15: TikTok | C15: Prospecting | Broad | EG | D15: TT-UGC-Trend | E15: =SUMIFS('Ad Data'!$G$2:$G$6000,'Ad Data'!$C$2:$C$6000,$A15,'Ad Data'!$A$2:$A$6000,">="&'KPI Calc'!$B$4,'Ad Data'!$A$2:$A$6000,"<="&'KPI Calc'!$C$4) | F15: =SUMIFS('Ad Data'!$H$2:$H$6000,'Ad Data'!$C$2:$C$6000,$A15,'Ad Data'!$A$2:$A$6000,">="&'KPI Calc'!$B$4,'Ad Data'!$A$2:$A$6000,"<="&'KPI Calc'!$C$4) | G15: =SUMIFS('Ad Data'!$I$2:$I$6000,'Ad Data'!$C$2:$C$6000,$A15,'Ad Data'!$A$2:$A$6000,">="&'KPI Calc'!$B$4,'Ad Data'!$A$2:$A$6000,"<="&'KPI Calc'!$C$4) | H15: =IFERROR(G15/F15,0) | I15: =SUMIFS('Ad Data'!$J$2:$J$6000,'Ad Data'!$C$2:$C$6000,$A15,'Ad Data'!$A$2:$A$6000,">="&'KPI Calc'!$B$4,'Ad Data'!$A$2:$A$6000,"<="&'KPI Calc'!$C$4) | J15: =SUMIFS('Ad Data'!$K$2:$K$6000,'Ad Data'!$C$2:$C$6000,$A15,'Ad Data'!$A$2:$A$6000,">="&'KPI Calc'!$B$4,'Ad Data'!$A$2:$A$6000,"<="&'KPI Calc'!$C$4) | K15: =IFERROR(J15/E15,0) | L15: =IFERROR(E15/I15,0) | M15: =IFERROR(J15/I15,0) | N15: =IF(E15=0,"No spend in period",IF(K15>=MAX('KPI Calc'!$B$35*1.3,0.01),"Scale — put more budget here",IF(K15>='KPI Calc'!$B$35,"Working — maintain and refresh creative","Below breakeven — fix the page or cut it")))
A16: UGC | Trend audio | v2 | B16: TikTok | C16: Prospecting | Broad | EG | D16: TT-UGC-Trend | E16: =SUMIFS('Ad Data'!$G$2:$G$6000,'Ad Data'!$C$2:$C$6000,$A16,'Ad Data'!$A$2:$A$6000,">="&'KPI Calc'!$B$4,'Ad Data'!$A$2:$A$6000,"<="&'KPI Calc'!$C$4) | F16: =SUMIFS('Ad Data'!$H$2:$H$6000,'Ad Data'!$C$2:$C$6000,$A16,'Ad Data'!$A$2:$A$6000,">="&'KPI Calc'!$B$4,'Ad Data'!$A$2:$A$6000,"<="&'KPI Calc'!$C$4) | G16: =SUMIFS('Ad Data'!$I$2:$I$6000,'Ad Data'!$C$2:$C$6000,$A16,'Ad Data'!$A$2:$A$6000,">="&'KPI Calc'!$B$4,'Ad Data'!$A$2:$A$6000,"<="&'KPI Calc'!$C$4) | H16: =IFERROR(G16/F16,0) | I16: =SUMIFS('Ad Data'!$J$2:$J$6000,'Ad Data'!$C$2:$C$6000,$A16,'Ad Data'!$A$2:$A$6000,">="&'KPI Calc'!$B$4,'Ad Data'!$A$2:$A$6000,"<="&'KPI Calc'!$C$4) | J16: =SUMIFS('Ad Data'!$K$2:$K$6000,'Ad Data'!$C$2:$C$6000,$A16,'Ad Data'!$A$2:$A$6000,">="&'KPI Calc'!$B$4,'Ad Data'!$A$2:$A$6000,"<="&'KPI Calc'!$C$4) | K16: =IFERROR(J16/E16,0) | L16: =IFERROR(E16/I16,0) | M16: =IFERROR(J16/I16,0) | N16: =IF(E16=0,"No spend in period",IF(K16>=MAX('KPI Calc'!$B$35*1.3,0.01),"Scale — put more budget here",IF(K16>='KPI Calc'!$B$35,"Working — maintain and refresh creative","Below breakeven — fix the page or cut it")))
A17: Spark ad | Creator A | B17: TikTok | C17: Spark | Creator A | D17: TT-Spark-CreatorA | E17: =SUMIFS('Ad Data'!$G$2:$G$6000,'Ad Data'!$C$2:$C$6000,$A17,'Ad Data'!$A$2:$A$6000,">="&'KPI Calc'!$B$4,'Ad Data'!$A$2:$A$6000,"<="&'KPI Calc'!$C$4) | F17: =SUMIFS('Ad Data'!$H$2:$H$6000,'Ad Data'!$C$2:$C$6000,$A17,'Ad Data'!$A$2:$A$6000,">="&'KPI Calc'!$B$4,'Ad Data'!$A$2:$A$6000,"<="&'KPI Calc'!$C$4) | G17: =SUMIFS('Ad Data'!$I$2:$I$6000,'Ad Data'!$C$2:$C$6000,$A17,'Ad Data'!$A$2:$A$6000,">="&'KPI Calc'!$B$4,'Ad Data'!$A$2:$A$6000,"<="&'KPI Calc'!$C$4) | H17: =IFERROR(G17/F17,0) | I17: =SUMIFS('Ad Data'!$J$2:$J$6000,'Ad Data'!$C$2:$C$6000,$A17,'Ad Data'!$A$2:$A$6000,">="&'KPI Calc'!$B$4,'Ad Data'!$A$2:$A$6000,"<="&'KPI Calc'!$C$4) | J17: =SUMIFS('Ad Data'!$K$2:$K$6000,'Ad Data'!$C$2:$C$6000,$A17,'Ad Data'!$A$2:$A$6000,">="&'KPI Calc'!$B$4,'Ad Data'!$A$2:$A$6000,"<="&'KPI Calc'!$C$4) | K17: =IFERROR(J17/E17,0) | L17: =IFERROR(E17/I17,0) | M17: =IFERROR(J17/I17,0) | N17: =IF(E17=0,"No spend in period",IF(K17>=MAX('KPI Calc'!$B$35*1.3,0.01),"Scale — put more budget here",IF(K17>='KPI Calc'!$B$35,"Working — maintain and refresh creative","Below breakeven — fix the page or cut it")))

Sheet Benchmarks
A1: Benchmarks
A2: These thresholds decide every Status column in the kit. Retune them per account.
A3: All amounts in EGP. Change the currency label on 'Start Here' after you copy this file.
A4: ⚠ The starting numbers below are placeholders so the status columns work on day one — they are not industry truth. Replace them with this client's own trailing 90-day range by month three. A benchmark you didn't measure is a guess, and clients can smell a guess.
A6: Metric | B6: Your value | C6: Weak | D6: Watch | E6: Target | F6: Strong | G6: Status | H6: If it's below target, look here first
A7: CPM | B7: ='KPI Calc'!B19 | C7: 140 | D7: 95 | E7: 72 | F7: 55 | G7: =IF($B7=0,"—",IF($B7<=F7,"Strong",IF($B7<=E7,"Target",IF($B7<=D7,"Watch","Weak")))) | H7: Auction pressure, audience saturation, or broad targeting diluting the mix.
A8: CPC | B8: ='KPI Calc'!B20 | C8: 9 | D8: 6.5 | E8: 5 | F8: 3.5 | G8: =IF($B8=0,"—",IF($B8<=F8,"Strong",IF($B8<=E8,"Target",IF($B8<=D8,"Watch","Weak")))) | H8: Mostly CPM plus CTR. If CPC is high but CTR is fine, look at placement and audience.
A9: CTR | B9: ='KPI Calc'!B21 | C9: 0.008 | D9: 0.012 | E9: 0.018 | F9: 0.028 | G9: =IF($B9=0,"—",IF($B9>=F9,"Strong",IF($B9>=E9,"Target",IF($B9>=D9,"Watch","Weak")))) | H9: The creative hook — first 3 seconds of video, first line of primary text.
A10: Meta click to landing page | B10: ='KPI Calc'!B27 | C10: 0.45 | D10: 0.6 | E10: 0.72 | F10: 0.85 | G10: =IF($B10=0,"—",IF($B10>=F10,"Strong",IF($B10>=E10,"Target",IF($B10>=D10,"Watch","Weak")))) | H10: Page speed and mobile load. A technical problem wearing a media costume.
A11: Click to add to cart | B11: ='KPI Calc'!B23 | C11: 0.03 | D11: 0.055 | E11: 0.08 | F11: 0.13 | G11: =IF($B11=0,"—",IF($B11>=F11,"Strong",IF($B11>=E11,"Target",IF($B11>=D11,"Watch","Weak")))) | H11: Product page: price positioning, imagery, reviews, delivery promise.
A12: Add to cart to checkout | B12: ='KPI Calc'!B24 | C12: 0.18 | D12: 0.3 | E12: 0.45 | F12: 0.6 | G12: =IF($B12=0,"—",IF($B12>=F12,"Strong",IF($B12>=E12,"Target",IF($B12>=D12,"Watch","Weak")))) | H12: Shipping cost, surprise fees, forced account creation.
A13: Checkout to purchase | B13: ='KPI Calc'!B25 | C13: 0.35 | D13: 0.5 | E13: 0.65 | F13: 0.78 | G13: =IF($B13=0,"—",IF($B13>=F13,"Strong",IF($B13>=E13,"Target",IF($B13>=D13,"Watch","Weak")))) | H13: Payment methods, cash on delivery, trust badges, retargeting coverage.
A14: Click to purchase CVR | B14: ='KPI Calc'!B26 | C14: 0.008 | D14: 0.015 | E14: 0.025 | F14: 0.04 | G14: =IF($B14=0,"—",IF($B14>=F14,"Strong",IF($B14>=E14,"Target",IF($B14>=D14,"Watch","Weak")))) | H14: End-to-end site conversion on paid clicks. Compare to this account's own history.
A15: Frequency | B15: ='KPI Calc'!B22 | C15: 5 | D15: 3.5 | E15: 2.4 | F15: 1.5 | G15: =IF($B15=0,"—",IF($B15<=F15,"Strong",IF($B15<=E15,"Target",IF($B15<=D15,"Watch","Weak")))) | H15: Creative fatigue. Above target, refresh assets before adding budget.
A16: AOV | B16: ='KPI Calc'!B29 | C16: 450 | D16: 550 | E16: 650 | F16: 800 | G16: =IF($B16=0,"—",IF($B16>=F16,"Strong",IF($B16>=E16,"Target",IF($B16>=D16,"Watch","Weak")))) | H16: Placeholder ladder — replace with this account's own trailing range.
A17: Revenue per 1,000 impressions | B17: ='KPI Calc'!B31 | C17: 80 | D17: 120 | E17: 170 | F17: 250 | G17: =IF($B17=0,"—",IF($B17>=F17,"Strong",IF($B17>=E17,"Target",IF($B17>=D17,"Watch","Weak")))) | H17: The cleanest single measure of end-to-end media efficiency.
A18: ROAS | B18: ='KPI Calc'!B30 | C18: 1.5 | D18: 2 | E18: 2.6 | F18: 3.5 | G18: =IF($B18=0,"—",IF($B18>=F18,"Strong",IF($B18>=E18,"Target",IF($B18>=D18,"Watch","Weak")))) | H18: Never set a target below breakeven ROAS. Weak here sits below breakeven on purpose.
A19: Breakeven ROAS | B19: ='KPI Calc'!B35 | C19: 3 | D19: 2.4 | E19: 2 | F19: 1.6 | G19: =IF($B19=0,"—",IF($B19<=F19,"Strong",IF($B19<=E19,"Target",IF($B19<=D19,"Watch","Weak")))) | H19: Calculated from the client's own margin inputs. Do not overwrite this row.
A20: POAS (profit on ad spend) | B20: ='KPI Calc'!B37 | C20: 0 | D20: 0.15 | E20: 0.35 | F20: 0.6 | G20: =IF($B20=0,"—",IF($B20>=F20,"Strong",IF($B20>=E20,"Target",IF($B20>=D20,"Watch","Weak")))) | H20: Profit per unit of spend. The number to move once ROAS is acceptable.
A21: Contribution margin % | B21: ='KPI Calc'!B33 | C21: 0.25 | D21: 0.35 | E21: 0.45 | F21: 0.55 | G21: =IF($B21=0,"—",IF($B21>=F21,"Strong",IF($B21>=E21,"Target",IF($B21>=D21,"Watch","Weak")))) | H21: Driven by the client's cost inputs on KPI Calc, cells J5:J7.
A23: How status is decided
A24: Higher is better (CTR, rates, AOV, ROAS, POAS): Strong ≥ F, Target ≥ E, Watch ≥ D, otherwise Weak.
A25: Lower is better (CPM, CPC, Frequency, Breakeven ROAS): the same ladder, mirrored.

Sheet Health Check
A1: Health Check
A2: Run this before anything goes to a client. Data errors look exactly like performance problems.
A5: DATA COVERAGE | E5: WHAT COUNTS AS 'GOOD'
A6: Rows in the current period | B6: =COUNTIFS(Fundamentals!$A$2:$A$6000,">="&'KPI Calc'!$B$4,Fundamentals!$A$2:$A$6000,"<="&'KPI Calc'!$C$4) | C6: Zero here means your date cells and your data don't overlap. Start here. | E6: There is no universal good CPM.
A7: Distinct days present | B7: =SUMPRODUCT((COUNTIFS(Fundamentals!$A$2:$A$6000,Fundamentals!$A$2:$A$6000,Fundamentals!$A$2:$A$6000,">="&'KPI Calc'!$B$4,Fundamentals!$A$2:$A$6000,"<="&'KPI Calc'!$C$4)>0)/COUNTIF(Fundamentals!$A$2:$A$6000,Fundamentals!$A$2:$A$6000&"")) | C7: Should roughly equal the days in your period, per platform. | E7: A CPM of 180 EGP is excellent for one category and fatal for another. The status column in this file compares this account against thresholds you control — start with the placeholders, then replace them with this client's own 90-day trailing range. That is the only benchmark that survives a client asking "compared to what?"
A8: Days in the period (calendar) | B8: ='KPI Calc'!$C$4-'KPI Calc'!$B$4+1 | C8: Compare with the row above. A big gap means missing sync days.
A9: First date in the data | B9: =IFERROR(MIN(Fundamentals!$A$2:$A$6000),0) | C9: Sanity-check the year.
A10: Last date in the data | B10: =IFERROR(MAX(Fundamentals!$A$2:$A$6000),0) | C10: Should be yesterday or today if the pipeline is healthy.
A11: Meta rows in period | B11: =COUNTIFS(Fundamentals!$A$2:$A$6000,">="&'KPI Calc'!$B$4,Fundamentals!$A$2:$A$6000,"<="&'KPI Calc'!$C$4,Fundamentals!$B$2:$B$6000,"Meta")
A12: TikTok rows in period | B12: =COUNTIFS(Fundamentals!$A$2:$A$6000,">="&'KPI Calc'!$B$4,Fundamentals!$A$2:$A$6000,"<="&'KPI Calc'!$C$4,Fundamentals!$B$2:$B$6000,"TikTok")
A15: CHECKS — red means fix the DATA, not the campaign
A16: Check | B16: Status | C16: Why it matters
A17: Data exists for the selected period | B17: =IF('KPI Calc'!$B$10>0,"OK","FIX") | C17: No impressions in the period means the date cells are wrong.
A18: Clicks never exceed impressions | B18: =IF('KPI Calc'!$B$12>'KPI Calc'!$B$10,"FIX","OK") | C18: A clicks > impressions read almost always means the wrong click column was pulled.
A19: Purchases never exceed clicks | B19: =IF('KPI Calc'!$B$16>'KPI Calc'!$B$12,"FIX","OK") | C19: Either a view-through-heavy attribution window or mismatched date ranges.
A20: Add to cart never exceeds clicks | B20: =IF('KPI Calc'!$B$14>'KPI Calc'!$B$12,"CHECK","OK") | C20: Cross-platform ATC can exceed clicks if windows differ between platforms.
A21: Reach never exceeds impressions | B21: =IF('KPI Calc'!$B$11>'KPI Calc'!$B$10,"FIX","OK") | C21: Reach is deduplicated, so this is a hard rule.
A22: Revenue is present | B22: =IF('KPI Calc'!$B$17<=0,"FIX","OK") | C22: Without purchase value there is no ROAS, no AOV and no story to tell.
A23: Ad spend reconciles to ad-level spend | B23: =IF(ABS(SUM('Ad Data'!$G$2:$G$6000)-'KPI Calc'!$B$9)/MAX(1,'KPI Calc'!$B$9)>0.05,"CHECK","OK") | C23: More than 5% apart means the ad-level export is incomplete or a different date range.
A24: Ad-level purchases reconcile | B24: =IF(ABS(SUM('Ad Data'!$J$2:$J$6000)-'KPI Calc'!$B$16)/MAX(1,'KPI Calc'!$B$16)>0.08,"CHECK","OK") | C24: Ad-level and account-level purchase counts should be close.
A25: Business inputs are filled in | B25: =IF(OR('KPI Calc'!$J$5<=0,'KPI Calc'!$J$7<=0),"FIX","OK") | C25: COGS % and shipping per order drive every profit number in the kit.
A26: Contribution margin is plausible | B26: =IF(OR('KPI Calc'!$B$33<=0,'KPI Calc'!$B$33>=1),"CHECK","OK") | C26: A margin outside 0–100% means a cost input is wrong.
A27: No blank platforms in Fundamentals | B27: =IF(COUNTIFS(Fundamentals!$B$2:$B$6000,"")>1,"CHECK","OK") | C27: Blank platform cells break the platform split on the Dashboard.
A28: Benchmarks retuned for this account | B28: =IF(Benchmarks!$D$16=0,"CHECK","OK") | C28: Until you replace the placeholder thresholds, every Status column is a guess.
A30: =IF(COUNTIF(B17:B28,"FIX")>0,"⛔ "&COUNTIF(B17:B28,"FIX")&" check(s) need fixing before you report these numbers.",IF(COUNTIF(B17:B28,"CHECK")>0,"⚠ "&COUNTIF(B17:B28,"CHECK")&" thing(s) to verify. They are usually benign — but verify them.","✅ All "&COUNTA(B17:B28)&" checks passed. This data is safe to report."))
