Workbook

Sheet _Inputs
A1: INTERNAL — this tab holds every number in the report. Do not send it to the client.
A2: Paste from the automation's report sheet, or type your platform numbers. Every other tab reads from here.
A4: COVER DETAILS
A5: Client / brand name | B5: Northwind Supply Co.
A6: Reporting period | B6: September 2026
A7: Compared against | B7: August 2026
A8: Prepared by | B8: Your Agency Name
A9: Report date | B9: 46307
A10: Currency | B10: EGP
A11: COMBINED — mirrors the automation's 'Combined' tab
A12: Metric | B12: Meta | C12: TikTok | D12: Combined
A13: Spend | B13: 93855.44 | C13: 42275.18 | D13: 136130.62
A14: Purchases | B14: 377 | C14: 193 | D14: 570
A15: Cost Per Purchase | B15: 248.9534 | C15: 219.0424 | D15: 238.8256
A16: Purchases Value | B16: 258908.18 | C16: 118272.29 | D16: 377180.47
A17: ROAS | B17: 2.7586 | C17: 2.7977 | D17: 2.7707
A18: AOV | B18: 686.7591 | C18: 612.8098 | D18: 661.7201
A20: META OVERVIEW — mirrors the automation's 'Meta Overview' tab
A21: Metric | B21: This period | C21: August 2026
A22: Spend | B22: 93855.44 | C22: 104835.73
A23: Outbound CTR | B23: 0.0159 | C23: 0.0162
A24: Impressions | B24: 1242419 | C24: 1522648
A25: Reach | B25: 538195 | C25: 678549
A26: Frequency | B26: 2.3085 | C26: 2.244
A27: Adds to cart | B27: 1064 | C27: 1351
A28: Initiate Checkout | B28: 492 | C28: 645
A29: Purchases | B29: 377 | C29: 480
A30: Cost Per Purchase | B30: 248.9534 | C30: 218.4078
A31: Purchases Value | B31: 258908.18 | C31: 332731.92
A32: ROAS | B32: 2.7586 | C32: 3.1738
A33: AOV | B33: 686.7591 | C33: 693.1915
A36: TIKTOK OVERVIEW — mirrors the automation's 'TikTok Overview' tab
A37: Metric | B37: This period | C37: August 2026
A38: Spend | B38: 42275.18 | C38: 48624.75
A39: CPM | B39: 49.5442 | C39: 45.4636
A40: CTR | B40: 0.0123 | C40: 0.0118
A41: Impressions | B41: 853282 | C41: 1069531
A42: Reach | B42: 443781 | C42: 550900
A43: Frequency | B43: 1.9228 | C43: 1.9414
A44: Adds to cart | B44: 681 | C44: 836
...

Sheet Cover
B6: MONTHLY PERFORMANCE REPORT
B8: =_Inputs!$B$5
B10: =_Inputs!$B$6&" · compared with "&_Inputs!$B$7
B13: ="Prepared by "&_Inputs!$B$8&" · "&TEXT(_Inputs!$B$9,"yyyy-mm-dd")
B18: Spend | C18: Revenue | D18: ROAS | E18: Purchases
B19: =_Inputs!$D$13 | C19: =_Inputs!$D$16 | D19: =_Inputs!$D$17 | E19: =_Inputs!$D$14
B22: ="Every number in this report traces back to a daily row pulled directly from Meta's and TikTok's own reporting APIs. Nothing here is typed in by hand, and nothing is estimated."
B27: ="Amounts in "&_Inputs!$B$10&". Reporting window "&_Inputs!$B$6&"."

Sheet Executive Summary
A1: =_Inputs!$B$5
A2: ="Executive summary · "&_Inputs!$B$6&" compared with "&_Inputs!$B$7
A4: AT A GLANCE
A5: SPEND | B5: REVENUE | C5: ROAS | D5: PURCHASES | E5: COST PER PURCHASE | F5: AOV
A6: =_Inputs!$D$13 | B6: =_Inputs!$D$16 | C6: =_Inputs!$D$17 | D6: =_Inputs!$D$14 | E6: =_Inputs!$D$15 | F6: =_Inputs!$D$18
A7: =SUM(_Inputs!$C$22,_Inputs!$C$38) | B7: =SUM(_Inputs!$C$31,_Inputs!$C$48) | C7: =IFERROR(SUM(_Inputs!$C$31,_Inputs!$C$48)/SUM(_Inputs!$C$22,_Inputs!$C$38),0) | D7: =SUM(_Inputs!$C$29,_Inputs!$C$46) | E7: =IFERROR(SUM(_Inputs!$C$22,_Inputs!$C$38)/SUM(_Inputs!$C$29,_Inputs!$C$46),0) | F7: =IFERROR(SUM(_Inputs!$C$31,_Inputs!$C$48)/SUM(_Inputs!$C$29,_Inputs!$C$46),0)
A9: Spend | B9: Revenue | C9: ROAS | D9: Purchases | E9: Cost per purchase | F9: AOV
A10: =IFERROR(=_Inputs!$D$13/=SUM(_Inputs!$C$22,_Inputs!$C$38)-1,0) | B10: =IFERROR(=_Inputs!$D$16/=SUM(_Inputs!$C$31,_Inputs!$C$48)-1,0) | C10: =IFERROR(=_Inputs!$D$17/=IFERROR(SUM(_Inputs!$C$31,_Inputs!$C$48)/SUM(_Inputs!$C$22,_Inputs!$C$38),0)-1,0) | D10: =IFERROR(=_Inputs!$D$14/=SUM(_Inputs!$C$29,_Inputs!$C$46)-1,0) | E10: =IFERROR(=_Inputs!$D$15/=IFERROR(SUM(_Inputs!$C$22,_Inputs!$C$38)/SUM(_Inputs!$C$29,_Inputs!$C$46),0)-1,0) | F10: =IFERROR(=_Inputs!$D$18/=IFERROR(SUM(_Inputs!$C$31,_Inputs!$C$48)/SUM(_Inputs!$C$29,_Inputs!$C$46),0)-1,0)
A11: =IF(A10=0,"",IF(A10>0,"▲ ","▼ ")&TEXT(ABS(A10),"0.0%")) | B11: =IF(B10=0,"",IF(B10>0,"▲ ","▼ ")&TEXT(ABS(B10),"0.0%")) | C11: =IF(C10=0,"",IF(C10>0,"▲ ","▼ ")&TEXT(ABS(C10),"0.0%")) | D11: =IF(D10=0,"",IF(D10>0,"▲ ","▼ ")&TEXT(ABS(D10),"0.0%")) | E11: =IF(E10=0,"",IF(E10>0,"▲ ","▼ ")&TEXT(ABS(E10),"0.0%")) | F11: =IF(F10=0,"",IF(F10>0,"▲ ","▼ ")&TEXT(ABS(F10),"0.0%"))
A13: WHAT HAPPENED — written from the numbers, then edited by a human
A14: The headline
A15: ="We invested "&TEXT(ROUND(A6,0),"#,##0")&" and generated "&TEXT(ROUND(B6,0),"#,##0")&" in tracked revenue — a return of "&ROUND(C6,2)&"x against a breakeven of "&ROUND(_Inputs!$B$54,2)&"x. "&IF(C6>=_Inputs!$B$54,"Advertising paid for itself this month.","Advertising did not cover its own cost this month, and we are treating that as the primary issue to solve.")
A16: Where it came from
A17: ="Meta carried "&TEXT(IFERROR(_Inputs!$B$22/_Inputs!$D$13,0),"0%")&" of spend at "&ROUND(_Inputs!$B$32,2)&"x, and TikTok carried "&TEXT(IFERROR(_Inputs!$B$38/_Inputs!$D$13,0),"0%")&" at "&ROUND(_Inputs!$B$49,2)&"x. "&IF(_Inputs!$B$32>_Inputs!$B$49,"Meta was the more efficient channel this month.","TikTok was the more efficient channel this month.")
A18: What changed
A19: ="Return moved from "&ROUND(C7,2)&"x to "&ROUND(C6,2)&"x, and cost per purchase from "&TEXT(ROUND(E7,0),"#,##0")&" to "&TEXT(ROUND(E6,0),"#,##0")&". "&IF(C6>=C7,"Efficiency improved month on month.","Efficiency slipped month on month, and we know why.")
A20: What we are doing about it
A21: =IF(_Inputs!$B$58="","Fill this in on the _Inputs tab — what we are doing next month. Talk to the AI prompts file, prompt 1.",_Inputs!$B$58)
A22: What we need from you
A23: =IF(_Inputs!$B$60="","Fill this in on the _Inputs tab — one clear ask.",_Inputs!$B$60)

Sheet Performance
A1: Performance
A2: =_Inputs!$B$5&" · Meta, TikTok and combined · all amounts in "&_Inputs!$B$10
A4: COMBINED — the three numbers that matter
A5: Metric | B5: Meta | C5: TikTok | D5: Combined | E5: Compare (Combined) | F5: Change | G5: Read
A6: Spend | B6: =_Inputs!$B$13 | C6: =_Inputs!$C$13 | D6: =_Inputs!$D$13 | E6: =SUM(_Inputs!$C$22,_Inputs!$C$38) | F6: =IFERROR(D6/E6-1,0) | G6: =IF(F6>0,"More budget deployed than last period.","Less budget deployed than last period.")
A7: Purchases | B7: =_Inputs!$B$14 | C7: =_Inputs!$C$14 | D7: =_Inputs!$D$14 | E7: =SUM(_Inputs!$C$29,_Inputs!$C$46) | F7: =IFERROR(D7/E7-1,0) | G7: =IF(F7>0,"More orders than last period.","Fewer orders than last period.")
A8: Cost Per Purchase | B8: =_Inputs!$B$15 | C8: =_Inputs!$C$15 | D8: =_Inputs!$D$15 | E8: =IFERROR(SUM(_Inputs!$C$22,_Inputs!$C$38)/SUM(_Inputs!$C$29,_Inputs!$C$46),0) | F8: =IFERROR(D8/E8-1,0) | G8: =IF(F8<0,"Orders got cheaper — efficiency improved.","Orders got more expensive — watch this closely.")
A9: Purchases Value | B9: =_Inputs!$B$16 | C9: =_Inputs!$C$16 | D9: =_Inputs!$D$16 | E9: =SUM(_Inputs!$C$31,_Inputs!$C$48) | F9: =IFERROR(D9/E9-1,0) | G9: =IF(F9>0,"Revenue grew month on month.","Revenue fell month on month.")
A10: ROAS | B10: =_Inputs!$B$17 | C10: =_Inputs!$C$17 | D10: =_Inputs!$D$17 | E10: =IFERROR(SUM(_Inputs!$C$31,_Inputs!$C$48)/SUM(_Inputs!$C$22,_Inputs!$C$38),0) | F10: =IFERROR(D10/E10-1,0) | G10: =IF(D10>=_Inputs!$B$54,"Above breakeven — advertising paid for itself.","Below breakeven — advertising did not pay for itself.")
A11: AOV | B11: =_Inputs!$B$18 | C11: =_Inputs!$C$18 | D11: =_Inputs!$D$18 | E11: =IFERROR(SUM(_Inputs!$C$31,_Inputs!$C$48)/SUM(_Inputs!$C$29,_Inputs!$C$46),0) | F11: =IFERROR(D11/E11-1,0) | G11: =IF(F11>0,"Basket size grew, which absorbs rising media costs.","Basket size shrank, which makes rising media costs harder to absorb.")
A13: SPEND MIX
A14: Channel | B14: Spend | C14: Share of spend | D14: Revenue | E14: ROAS | F14: Verdict
A15: Meta | B15: =_Inputs!$B$13 | C15: =IFERROR(B15/$D$13,0) | D15: =_Inputs!$B$16 | E15: =_Inputs!$B$17 | F15: =IF(E15>=_Inputs!$B$54,"Above breakeven","Below breakeven — under review")
A16: TikTok | B16: =_Inputs!$C$13 | C16: =IFERROR(B16/$D$13,0) | D16: =_Inputs!$C$16 | E16: =_Inputs!$C$17 | F16: =IF(E16>=_Inputs!$B$54,"Above breakeven","Below breakeven — under review")
A17: Total | B17: =SUM(B15:B16) | C17: =IFERROR(B17/$D$13,0) | D17: =SUM(D15:D16) | E17: =IFERROR(D17/B17,0) | F17: =IF(E17>=_Inputs!$B$54,"Above breakeven","Below breakeven")
A19: READ THIS AGAINST BREAKEVEN
A20: ="Breakeven ROAS for this business is "&ROUND(_Inputs!$B$54,2)&"x. That is calculated from your own cost structure — product cost, shipping, payment fees and returns — not from an industry rule of thumb."
A21: ="You delivered "&ROUND(_Inputs!$D$17,2)&"x. "&IF(_Inputs!$D$17>=_Inputs!$B$54,"That means every unit spent on advertising returned a profit above its own cost.","That means advertising did not cover its own cost this month.")
A22: ="Target for next month is "&ROUND(_Inputs!$B$55,2)&"x. Anything at or above breakeven keeps the account compounding; anything below it needs a structural fix, not a bigger budget."

Sheet Platform Detail
A1: Platform detail
A2: =_Inputs!$B$5&" · this period against last period"
A4: META | F4: TIKTOK
A5: Metric | B5: This period | C5: August 2026 | F5: Metric | G5: This period | H5: August 2026
A6: Spend | B6: =_Inputs!$B$22 | C6: =_Inputs!$C$22 | F6: Spend | G6: =_Inputs!$B$38 | H6: =_Inputs!$C$38
A7: Outbound CTR | B7: =_Inputs!$B$23 | C7: =_Inputs!$C$23 | F7: CPM | G7: =_Inputs!$B$39 | H7: =_Inputs!$C$39
A8: Impressions | B8: =_Inputs!$B$24 | C8: =_Inputs!$C$24 | F8: CTR | G8: =_Inputs!$B$40 | H8: =_Inputs!$C$40
A9: Reach | B9: =_Inputs!$B$25 | C9: =_Inputs!$C$25 | F9: Impressions | G9: =_Inputs!$B$41 | H9: =_Inputs!$C$41
A10: Frequency | B10: =_Inputs!$B$26 | C10: =_Inputs!$C$26 | F10: Reach | G10: =_Inputs!$B$42 | H10: =_Inputs!$C$42
A11: Adds to cart | B11: =_Inputs!$B$27 | C11: =_Inputs!$C$27 | F11: Frequency | G11: =_Inputs!$B$43 | H11: =_Inputs!$C$43
A12: Initiate Checkout | B12: =_Inputs!$B$28 | C12: =_Inputs!$C$28 | F12: Adds to cart | G12: =_Inputs!$B$44 | H12: =_Inputs!$C$44
A13: Purchases | B13: =_Inputs!$B$29 | C13: =_Inputs!$C$29 | F13: Initiate Checkout | G13: =_Inputs!$B$45 | H13: =_Inputs!$C$45
A14: Cost Per Purchase | B14: =_Inputs!$B$30 | C14: =_Inputs!$C$30 | F14: Purchases | G14: =_Inputs!$B$46 | H14: =_Inputs!$C$46
A15: Purchases Value | B15: =_Inputs!$B$31 | C15: =_Inputs!$C$31 | F15: Cost Per Purchase | G15: =_Inputs!$B$47 | H15: =_Inputs!$C$47
A16: ROAS | B16: =_Inputs!$B$32 | C16: =_Inputs!$C$32 | F16: Purchases Value | G16: =_Inputs!$B$48 | H16: =_Inputs!$C$48
A17: AOV | B17: =_Inputs!$B$33 | C17: =_Inputs!$C$33 | F17: ROAS | G17: =_Inputs!$B$49 | H17: =_Inputs!$C$49
F18: AOV | G18: =_Inputs!$B$50 | H18: =_Inputs!$C$50
A20: ="A note on reach: the numbers above sum daily reach across the month, so they overstate the number of distinct people. Platform reach is deduplicated within a day, not across a month. Treat it as a trend, not a headcount."

Sheet Combined
A1: Combined — Meta + TikTok
A2: =_Inputs!$B$5&" · "&_Inputs!$B$6&" against "&_Inputs!$B$7
A3: This is the only tab where the two platforms share a row — everything else keeps them apart on purpose, so a weak channel cannot hide behind a strong one.
A5: THE TWO PLATFORMS TOGETHER
A6: Metric | B6: Meta | C6: TikTok | D6: Combined | E6: Meta share | F6: TikTok share
A7: Spend | B7: =_Inputs!$B$22 | C7: =_Inputs!$B$38 | D7: =_Inputs!$D$13 | E7: =IFERROR(B7/D7,"") | F7: =IFERROR(C7/D7,"")
A8: Impressions | B8: =_Inputs!$B$24 | C8: =_Inputs!$B$41 | D8: =B8+C8 | E8: =IFERROR(B8/D8,"") | F8: =IFERROR(C8/D8,"")
A9: Clicks | B9: =_Inputs!$B$23*_Inputs!$B$24 | C9: =_Inputs!$B$40*_Inputs!$B$41 | D9: =B9+C9 | E9: =IFERROR(B9/D9,"") | F9: =IFERROR(C9/D9,"") | G9: derived: CTR × impressions (the automation payload has no click column)
A10: Adds to cart | B10: =_Inputs!$B$27 | C10: =_Inputs!$B$44 | D10: =B10+C10
A11: Initiate Checkout | B11: =_Inputs!$B$28 | C11: =_Inputs!$B$45 | D11: =B11+C11
A12: Purchases | B12: =_Inputs!$B$29 | C12: =_Inputs!$B$46 | D12: =_Inputs!$D$14
A13: Purchases Value | B13: =_Inputs!$B$31 | C13: =_Inputs!$B$48 | D13: =_Inputs!$D$16 | E13: =IFERROR(B13/D13,"") | F13: =IFERROR(C13/D13,"")
A14: Reach (sum of days) | B14: =_Inputs!$B$25 | C14: =_Inputs!$B$42 | D14: =B14+C14 | G14: sum of daily reach — a trend, not a headcount
A15: CPM | B15: =IFERROR(_Inputs!$B$22/_Inputs!$B$24*1000,0) | C15: =_Inputs!$B$39 | D15: =IFERROR(D7/D8*1000,0) | G15: Meta CPM is derived from spend ÷ impressions
A16: CTR | B16: =_Inputs!$B$23 | C16: =_Inputs!$B$40 | D16: =IFERROR(D9/D8,0)
A17: Frequency | B17: =_Inputs!$B$26 | C17: =_Inputs!$B$43 | D17: =IFERROR(D8/D14,0) | G17: impressions ÷ reach
A18: Cost Per Purchase | B18: =_Inputs!$B$30 | C18: =_Inputs!$B$47 | D18: =_Inputs!$D$15
A19: ROAS | B19: =_Inputs!$B$32 | C19: =_Inputs!$B$49 | D19: =_Inputs!$D$17
A20: AOV | B20: =_Inputs!$B$33 | C20: =_Inputs!$B$50 | D20: =_Inputs!$D$18
A22: THE COMBINED FUNNEL
A23: Step | B23: Meta | C23: TikTok | D23: Combined | E23: Step rate | F23: Bar
A24: Impressions | B24: =_Inputs!$B$24 | C24: =_Inputs!$B$41 | D24: =B24+C24 | E24: =IFERROR(D25/D24,0) | F24: =REPT("█",ROUND(20*IFERROR(D25/D24,0),0))
A25: Clicks | B25: =_Inputs!$B$23*_Inputs!$B$24 | C25: =_Inputs!$B$40*_Inputs!$B$41 | D25: =B25+C25 | E25: =IFERROR(D26/D25,0) | F25: =REPT("█",ROUND(20*IFERROR(D26/D25,0),0))
A26: Adds to cart | B26: =_Inputs!$B$27 | C26: =_Inputs!$B$44 | D26: =B26+C26 | E26: =IFERROR(D27/D26,0) | F26: =REPT("█",ROUND(20*IFERROR(D27/D26,0),0))
A27: Initiate Checkout | B27: =_Inputs!$B$28 | C27: =_Inputs!$B$45 | D27: =B27+C27 | E27: =IFERROR(D28/D27,0) | F27: =REPT("█",ROUND(20*IFERROR(D28/D27,0),0))
A28: Purchases | B28: =_Inputs!$B$29 | C28: =_Inputs!$B$46 | D28: =B28+C28
A30: WHICH PLATFORM IS EARNING ITS KEEP
A31: Platform | B31: Share of spend | C31: Share of revenue | D31: Difference | E31: Read
A32: Meta | B32: =IFERROR(_Inputs!$B$22/_Inputs!$D$13,0) | C32: =IFERROR(_Inputs!$B$31/_Inputs!$D$16,0) | D32: =C32-B32 | E32: =IF(C32=0,"",IF(D32>0.02,"Pulling more than its weight — revenue share is ahead of spend share.",IF(D32<-0.02,"Costing more than it returns — spend share is ahead of revenue share.","Roughly balanced with its budget share.")))
A33: TikTok | B33: =IFERROR(_Inputs!$B$38/_Inputs!$D$13,0) | C33: =IFERROR(_Inputs!$B$48/_Inputs!$D$16,0) | D33: =C33-B33 | E33: =IF(C33=0,"",IF(D33>0.02,"Pulling more than its weight — revenue share is ahead of spend share.",IF(D33<-0.02,"Costing more than it returns — spend share is ahead of revenue share.","Roughly balanced with its budget share.")))
A34: ="Blended ROAS is "&ROUND(_Inputs!$D$17,2)&"x. Meta delivered "&ROUND(_Inputs!$B$32,2)&"x on "&TEXT(_Inputs!$B$22/_Inputs!$D$13,"0%")&" of the budget, TikTok "&ROUND(_Inputs!$B$49,2)&"x on "&TEXT(_Inputs!$B$38/_Inputs!$D$13,"0%")&". "&IF(_Inputs!$B$32>_Inputs!$B$49,"Meta is the more efficient channel this period.","TikTok is the more efficient channel this period.")

Sheet Top Ads
A1: Top Ads
A2: =_Inputs!$B$5&" · "&"Ranked by spend. Paste straight from the automation's Ad Performance tab."
A5: # | B5: Ad name | C5: Spend | D5: Purchases | E5: Revenue | F5: ROAS | G5: Cost/Purch. | H5: AOV | I5: Read
A6: 1 | B6: VID | Founder story | v4 | C6: 26161 | D6: 112 | E6: 76279 | F6: =IFERROR(E6/C6,0) | G6: =IFERROR(C6/D6,0) | H6: =IFERROR(E6/D6,0) | I6: =IF(C6=0,"",IF(F6>=_Inputs!$B$54*1.3,"Scale — strongest return in the set",IF(F6>=_Inputs!$B$54,"Keep and refresh the asset","Below breakeven — cut or rebuild")))
A7: 2 | B7: STATIC | Bundle offer | v2 | C7: 17134 | D7: 59 | E7: 40838 | F7: =IFERROR(E7/C7,0) | G7: =IFERROR(C7/D7,0) | H7: =IFERROR(E7/D7,0) | I7: =IF(C7=0,"",IF(F7>=_Inputs!$B$54*1.3,"Scale — strongest return in the set",IF(F7>=_Inputs!$B$54,"Keep and refresh the asset","Below breakeven — cut or rebuild")))
A8: 3 | B8: UGC | Problem-solution | v2 | C8: 14365 | D8: 69 | E8: 42528 | F8: =IFERROR(E8/C8,0) | G8: =IFERROR(C8/D8,0) | H8: =IFERROR(E8/D8,0) | I8: =IF(C8=0,"",IF(F8>=_Inputs!$B$54*1.3,"Scale — strongest return in the set",IF(F8>=_Inputs!$B$54,"Keep and refresh the asset","Below breakeven — cut or rebuild")))
A9: 4 | B9: VID | Founder story | v3 | C9: 12983 | D9: 41 | E9: 28152 | F9: =IFERROR(E9/C9,0) | G9: =IFERROR(C9/D9,0) | H9: =IFERROR(E9/D9,0) | I9: =IF(C9=0,"",IF(F9>=_Inputs!$B$54*1.3,"Scale — strongest return in the set",IF(F9>=_Inputs!$B$54,"Keep and refresh the asset","Below breakeven — cut or rebuild")))
A10: 5 | B10: VID | Review compilation | v1 | C10: 12497 | D10: 45 | E10: 31048 | F10: =IFERROR(E10/C10,0) | G10: =IFERROR(C10/D10,0) | H10: =IFERROR(E10/D10,0) | I10: =IF(C10=0,"",IF(F10>=_Inputs!$B$54*1.3,"Scale — strongest return in the set",IF(F10>=_Inputs!$B$54,"Keep and refresh the asset","Below breakeven — cut or rebuild")))
A11: 6 | B11: Spark ad | Creator A | C11: 10640 | D11: 63 | E11: 38122 | F11: =IFERROR(E11/C11,0) | G11: =IFERROR(C11/D11,0) | H11: =IFERROR(E11/D11,0) | I11: =IF(C11=0,"",IF(F11>=_Inputs!$B$54*1.3,"Scale — strongest return in the set",IF(F11>=_Inputs!$B$54,"Keep and refresh the asset","Below breakeven — cut or rebuild")))
A12: 7 | B12: UGC | Trend audio | v1 | C12: 9684 | D12: 29 | E12: 18149 | F12: =IFERROR(E12/C12,0) | G12: =IFERROR(C12/D12,0) | H12: =IFERROR(E12/D12,0) | I12: =IF(C12=0,"",IF(F12>=_Inputs!$B$54*1.3,"Scale — strongest return in the set",IF(F12>=_Inputs!$B$54,"Keep and refresh the asset","Below breakeven — cut or rebuild")))
A13: 8 | B13: STATIC | Bundle offer | v1 | C13: 8631 | D13: 30 | E13: 20597 | F13: =IFERROR(E13/C13,0) | G13: =IFERROR(C13/D13,0) | H13: =IFERROR(E13/D13,0) | I13: =IF(C13=0,"",IF(F13>=_Inputs!$B$54*1.3,"Scale — strongest return in the set",IF(F13>=_Inputs!$B$54,"Keep and refresh the asset","Below breakeven — cut or rebuild")))
A14: 9 | B14: UGC | Trend audio | v2 | C14: 7586 | D14: 32 | E14: 19473 | F14: =IFERROR(E14/C14,0) | G14: =IFERROR(C14/D14,0) | H14: =IFERROR(E14/D14,0) | I14: =IF(C14=0,"",IF(F14>=_Inputs!$B$54*1.3,"Scale — strongest return in the set",IF(F14>=_Inputs!$B$54,"Keep and refresh the asset","Below breakeven — cut or rebuild")))
A15: 10 | B15: STATIC | Discount 20% | v1 | C15: 7341 | D15: 51 | E15: 35224 | F15: =IFERROR(E15/C15,0) | G15: =IFERROR(C15/D15,0) | H15: =IFERROR(E15/D15,0) | I15: =IF(C15=0,"",IF(F15>=_Inputs!$B$54*1.3,"Scale — strongest return in the set",IF(F15>=_Inputs!$B$54,"Keep and refresh the asset","Below breakeven — cut or rebuild")))
A17: ="Spend above is "&TEXT(ROUND(SUM(C6:C15),0),"#,##0")&" against "&TEXT(ROUND(_Inputs!$D$13,0),"#,##0")&" total ad spend — a gap means some spend sits in ads not listed here."
A19: What to do with this table
A20: · | B20: Anything above 1.3× breakeven gets more budget — but raise it in steps and watch frequency, not in one jump.
A21: · | B21: Anything between breakeven and 1.3× is working. Keep it, and refresh the creative before it fatigues.
A22: · | B22: Anything below breakeven is losing money on every order. Fix the landing page or stop it. Do not 'optimise' it forever.
A23: · | B23: Look at cost per purchase against AOV, not against last month alone. A rising CPA with a rising AOV can still be progress.

Sheet Creatives
A1: Creatives
A2: =_Inputs!$B$5&" · "&"Grouped by creative key — the same asset across campaigns and ad sets."
A5: # | B5: Creative | C5: Spend | D5: Purchases | E5: Revenue | F5: ROAS | G5: Cost/Purch. | H5: AOV | I5: Read
A6: 1 | B6: UGC-Founder | C6: 43152 | D6: 153 | E6: 104431 | F6: =IFERROR(E6/C6,0) | G6: =IFERROR(C6/D6,0) | H6: =IFERROR(E6/D6,0) | I6: =IF(C6=0,"",IF(F6>=_Inputs!$B$54*1.3,"Scale — strongest return in the set",IF(F6>=_Inputs!$B$54,"Keep and refresh the asset","Below breakeven — cut or rebuild")))
A7: 2 | B7: Static-Bundle | C7: 25765 | D7: 89 | E7: 61435 | F7: =IFERROR(E7/C7,0) | G7: =IFERROR(C7/D7,0) | H7: =IFERROR(E7/D7,0) | I7: =IF(C7=0,"",IF(F7>=_Inputs!$B$54*1.3,"Scale — strongest return in the set",IF(F7>=_Inputs!$B$54,"Keep and refresh the asset","Below breakeven — cut or rebuild")))
A8: 3 | B8: TT-UGC-Trend | C8: 17270 | D8: 61 | E8: 37622 | F8: =IFERROR(E8/C8,0) | G8: =IFERROR(C8/D8,0) | H8: =IFERROR(E8/D8,0) | I8: =IF(C8=0,"",IF(F8>=_Inputs!$B$54*1.3,"Scale — strongest return in the set",IF(F8>=_Inputs!$B$54,"Keep and refresh the asset","Below breakeven — cut or rebuild")))
A9: 4 | B9: TT-UGC-ProbSol | C9: 14365 | D9: 69 | E9: 42528 | F9: =IFERROR(E9/C9,0) | G9: =IFERROR(C9/D9,0) | H9: =IFERROR(E9/D9,0) | I9: =IF(C9=0,"",IF(F9>=_Inputs!$B$54*1.3,"Scale — strongest return in the set",IF(F9>=_Inputs!$B$54,"Keep and refresh the asset","Below breakeven — cut or rebuild")))
A10: 5 | B10: UGC-Reviews | C10: 12497 | D10: 45 | E10: 31048 | F10: =IFERROR(E10/C10,0) | G10: =IFERROR(C10/D10,0) | H10: =IFERROR(E10/D10,0) | I10: =IF(C10=0,"",IF(F10>=_Inputs!$B$54*1.3,"Scale — strongest return in the set",IF(F10>=_Inputs!$B$54,"Keep and refresh the asset","Below breakeven — cut or rebuild")))
A11: 6 | B11: TT-Spark-CreatorA | C11: 10640 | D11: 63 | E11: 38122 | F11: =IFERROR(E11/C11,0) | G11: =IFERROR(C11/D11,0) | H11: =IFERROR(E11/D11,0) | I11: =IF(C11=0,"",IF(F11>=_Inputs!$B$54*1.3,"Scale — strongest return in the set",IF(F11>=_Inputs!$B$54,"Keep and refresh the asset","Below breakeven — cut or rebuild")))
A12: 7 | B12: Static-Discount | C12: 7341 | D12: 51 | E12: 35224 | F12: =IFERROR(E12/C12,0) | G12: =IFERROR(C12/D12,0) | H12: =IFERROR(E12/D12,0) | I12: =IF(C12=0,"",IF(F12>=_Inputs!$B$54*1.3,"Scale — strongest return in the set",IF(F12>=_Inputs!$B$54,"Keep and refresh the asset","Below breakeven — cut or rebuild")))
A13: 8 | B13: Carousel-Bestsellers | C13: 5101 | D13: 39 | E13: 26770 | F13: =IFERROR(E13/C13,0) | G13: =IFERROR(C13/D13,0) | H13: =IFERROR(E13/D13,0) | I13: =IF(C13=0,"",IF(F13>=_Inputs!$B$54*1.3,"Scale — strongest return in the set",IF(F13>=_Inputs!$B$54,"Keep and refresh the asset","Below breakeven — cut or rebuild")))
A15: ="Spend above is "&TEXT(ROUND(SUM(C6:C13),0),"#,##0")&" against "&TEXT(ROUND(_Inputs!$D$13,0),"#,##0")&" total ad spend — a gap means some spend sits in ads not listed here."
A17: What to do with this table
A18: · | B18: Anything above 1.3× breakeven gets more budget — but raise it in steps and watch frequency, not in one jump.
A19: · | B19: Anything between breakeven and 1.3× is working. Keep it, and refresh the creative before it fatigues.
A20: · | B20: Anything below breakeven is losing money on every order. Fix the landing page or stop it. Do not 'optimise' it forever.
A21: · | B21: Look at cost per purchase against AOV, not against last month alone. A rising CPA with a rising AOV can still be progress.

Sheet Weekly Trend
A1: Weekly trend
A2: =_Inputs!$B$5&" · week by week, ranked best ROAS first (matching the automation's Weekly tabs)"
A5: # | B5: Week | C5: Spend | D5: Purchases | E5: Revenue | F5: ROAS | G5: Cost/Purch. | H5: AOV | I5: Read
A6: 1 | B6: Sep 15 – Sep 21 | C6: 33113 | D6: 146 | E6: 97068 | F6: =IFERROR(E6/C6,0) | G6: =IFERROR(C6/D6,0) | H6: =IFERROR(E6/D6,0) | I6: =IF(F6="","",IF(F6>=_Inputs!$B$54*1.25,"Strongest week of the month",IF(F6>=_Inputs!$B$54,"Above breakeven","The soft week — this is the one to explain")))
A7: 2 | B7: Sep 29 – Sep 30 | C7: 9065 | D7: 40 | E7: 26355 | F7: =IFERROR(E7/C7,0) | G7: =IFERROR(C7/D7,0) | H7: =IFERROR(E7/D7,0) | I7: =IF(F7="","",IF(F7>=_Inputs!$B$54*1.25,"Strongest week of the month",IF(F7>=_Inputs!$B$54,"Above breakeven","The soft week — this is the one to explain")))
A8: 3 | B8: Sep 8 – Sep 14 | C8: 24856 | D8: 108 | E8: 70754 | F8: =IFERROR(E8/C8,0) | G8: =IFERROR(C8/D8,0) | H8: =IFERROR(E8/D8,0) | I8: =IF(F8="","",IF(F8>=_Inputs!$B$54*1.25,"Strongest week of the month",IF(F8>=_Inputs!$B$54,"Above breakeven","The soft week — this is the one to explain")))
A9: 4 | B9: Sep 1 – Sep 7 | C9: 35336 | D9: 150 | E9: 98715 | F9: =IFERROR(E9/C9,0) | G9: =IFERROR(C9/D9,0) | H9: =IFERROR(E9/D9,0) | I9: =IF(F9="","",IF(F9>=_Inputs!$B$54*1.25,"Strongest week of the month",IF(F9>=_Inputs!$B$54,"Above breakeven","The soft week — this is the one to explain")))
A10: 5 | B10: Sep 22 – Sep 28 | C10: 33761 | D10: 126 | E10: 84288 | F10: =IFERROR(E10/C10,0) | G10: =IFERROR(C10/D10,0) | H10: =IFERROR(E10/D10,0) | I10: =IF(F10="","",IF(F10>=_Inputs!$B$54*1.25,"Strongest week of the month",IF(F10>=_Inputs!$B$54,"Above breakeven","The soft week — this is the one to explain")))
A12: ="Spread between the best and worst week: "&ROUND(MAX(F6:F10)-MIN(F6:F10),2)&" ROAS points. "&"Weeks are ranked by return, exactly as the automation's Weekly tabs rank them. If the soft week is also the week you spent the most, that is the whole story of the month."

Sheet What We Did & Next
A1: What we did, and what happens next
A2: =_Inputs!$B$5&" · the part of the report the client actually reads"
A4: WHAT WE CHANGED THIS MONTH
A5: What we changed this month | B5: =_Inputs!$B$56 | C5: Name three things you actually did. Specifics beat adjectives: "launched four UGC concepts" not "optimised creative".
A10: WHAT WE LEARNED
A11: What we learned | B11: =_Inputs!$B$57 | C11: One insight the data proved. This is what you are paid for.
A16: WHAT WE ARE DOING NEXT MONTH
A17: What we are doing next month | B17: =_Inputs!$B$58 | C17: Two or three concrete moves, each tied to a number above.
A22: WHAT THE NUMBERS DON'T SHOW
A23: What the numbers don't show | B23: =_Inputs!$B$59 | C23: Stockouts, shipping delays, a price change, a competitor entering. Say it before the client finds it.
A28: WHAT WE NEED FROM YOU
A29: What we need from you | B29: =_Inputs!$B$60 | C29: One clear ask. New imagery, a price decision, a stock fix. Give them a job and they become a partner.
A34: HOW TO FILL THESE IN
A35: Don't write these from scratch. | B35: Open 05_AI_Prompts_Campaign_Performance.md and run Prompt 1 (the monthly narrative) on your _Inputs tab. It will draft all five blocks. Then edit for tone — delete anything that sounds like a machine, and cut it to half the length. The client reads the first sentence of each block.
A37: The tone rule | B37: Never explain a metric the client didn't ask about. Never hide a bad month. Lead with what changed and what you're doing about it — the numbers are evidence, not the message.

Sheet Dictionary
A1: What each number means
A2: Send this page with the report. It answers 80% of the follow-up questions before they're asked.
A4: Term | B4: In plain English | C4: Why it matters to you
A5: Ad spend | B5: What we put into Meta and TikTok this month. | C5: This is the investment. Everything else is the result of it.
A6: Impressions | B6: How many times our ads were shown. | C6: Volume of attention — not a result on its own.
A7: Reach | B7: How many people saw the ads (counted once per person per day). | C7: How many humans, roughly. It can't be added up across a month, so treat it as a trend.
A8: Frequency | B8: How many times, on average, each person saw us. | C8: Too low and you're under-spending; too high and people stop noticing us.
A9: CPM | B9: What it cost to show our ads a thousand times. | C9: The price of attention. It rises and falls with auction competition, not just our choices.
A10: CTR | B10: The share of people who clicked after seeing an ad. | C10: How well the creative earns attention.
A11: Clicks | B11: Visits to your site from our ads. | C11: The top of your sales funnel.
A12: Add to cart | B12: People who put something in their basket. | C12: Intent. This is where we see if the product page is doing its job.
A13: Initiate checkout | B13: People who started checking out. | C13: The last step before money moves.
A14: Purchases | B14: Orders attributed to our ads. | C14: The result we're judged on — reported inside the platform's attribution window, which is stated on every report.
A15: Purchases value / Revenue | B15: The value of those orders. | C15: This is what ROAS is built from.
... A21: Attribution window | B21: How long after clicking a platform still credits itself with a sale. | C21: We keep this fixed month to month so comparisons stay honest. It's stated on the report.
A23: ="All figures are pulled directly from Meta's and TikTok's own reporting APIs. There is no manual entry step between the platform and this report."
