Workbook

Sheet Start Here
B2: The Media Buyer's Client Reporting Kit
B3: KPI Calculator · the math engine
B5: What this file does
B6: It turns platform numbers (spend, impressions, clicks, purchases, revenue) into the two things a client actually asks about: what each order really costs you, and whether the ad spend made money. It also tells you your breakeven ROAS, which is the number most media buyers quote wrong.
B8: 1 | C8: Open the Calculator tab.
C9: Fill in the nine amber boxes under MEDIA INPUTS. That's your platform data.
B10: 2 | C10: Fill the nine amber boxes under BUSINESS INPUTS.
C11: These are the client's real costs: margin, shipping, fees, returns. If you don't have them, ask. This is the difference between a report and a guess.
B12: 3 | C12: Leave every grey cell alone.
C13: Grey = calculated. Nothing there needs typing.
B14: 4 | C14: Read THE VERDICT.
C15: Five plain-English sentences you can paste into a client email. They update live.
B16: 5 | C16: Check the sanity checks.
C17: Red rows mean the input data is wrong — fix the data before you trust the output.
B18: 6 | C18: Use Profit Bridge and Period Compare.
C19: Profit Bridge shows where every unit of revenue goes. Period Compare explains WHY ROAS moved, split into CPM / CTR / CVR / AOV.
B21: ONE SETTING
B22: Currency code | C22: EGP
B23: Change it by: | C23: Find-and-replace "EGP" with your currency code on the Calculator, Profit Bridge and Benchmarks tabs, then update the cell formats (Format ▸ Number ▸ Custom) where you want the symbol shown.
B25: The one rule
B26: Never report ROAS without breakeven ROAS next to it. | C26: A 2.4x ROAS sounds fine until you learn the client's breakeven is 2.8x. Every number in this kit is built to be read against breakeven, not against a vague idea of "good".

Sheet Calculator
A1: KPI Calculator
A2: Nine numbers in. Everything a client will ask you, out. A worked example (Meta, September 2026) is already loaded — overwrite the amber cells.
A3: All amounts in EGP. Change the currency label on 'Start Here' after you copy this file.
A5: 1 · MEDIA INPUTS — type in the amber cells | E5: 2 · BUSINESS INPUTS — the client's real costs
A6: Metric | B6: Value | C6: Where you get it | E6: Input | F6: Value | G6: Where you get it
A7: Ad spend | B7: 93855.44 | C7: Platform total, same period as everything below | E7: COGS (% of revenue) | F7: 0.3 | G7: Product cost ÷ selling price. Ask the client — don't assume 30%
A8: Impressions | B8: 1242419 | C8: Platform | E8: Shipping & fulfilment per order | F8: 72 | G8: What it costs to get an order out, including packaging
A9: Reach | B9: 538195 | C9: Platform — needed for frequency | E9: Payment processing fee (%) | F9: 0.03 | G9: Card / gateway fees. Usually 2–4%
A10: Clicks (link clicks) | B10: 19802 | C10: Outbound / link clicks, NOT all clicks | E10: Returns & refunds (% of revenue) | F10: 0.03 | G10: Real refund rate, not the aspirational one
A11: Landing page views | B11: 14836 | C11: Same platform as the clicks above. TikTok does not report LPV | E11: Other variable cost per order | F11: 0 | G11: Anything that scales with an order
A12: Adds to cart | B12: 1064 | C12: Platform, same attribution window | E12: Fixed monthly costs | F12: 25000 | G12: Excluding ads and agency fee
A13: Initiate checkout | B13: 492 | C13: Platform | E13: Agency / retainer fee (monthly) | F13: 18000 | G13: What you charge this client
A14: Purchases | B14: 377 | C14: Platform. Keep the window consistent month to month | E14: Target net margin (%) | F14: 0.15 | G14: The profit the client wants to keep AFTER ads
A15: Revenue (purchase value) | B15: 258908.18 | C15: Platform purchase value, not Shopify gross sales | E15: Blended revenue incl. organic | F15: 509193.63 | G15: All revenue, not just ads — for MER. Leave blank if unknown
A17: 3 · FUNNEL EFFICIENCY — calculated, do not type | E17: 4 · UNIT ECONOMICS & PROFIT — calculated, do not type
A18: Metric | B18: Value | C18: What it tells you | E18: Metric | F18: Value | G18: What it tells you
A19: CPM (cost per 1,000 impressions) | B19: =IFERROR(B7/B8*1000,0) | C19: What you paid for attention. Rising CPM is usually auction pressure, not your fault | E19: Revenue | F19: =B15 | G19: Everything below starts here
A20: CPC (cost per link click) | B20: =IFERROR(B7/B10,0) | C20: Cost of a visit. Moves with CPM and CTR | E20: Less: COGS | F20: =-IFERROR(B15*F7,0) | G20: Product cost
A21: CTR % | B21: =IFERROR(B10/B8,0) | C21: Creative hook strength. The only lever you can change fast | E21: Less: shipping & fulfilment | F21: =-IFERROR(B14*F8,0) | G21: Scales with orders, not revenue
A22: Frequency | B22: =IFERROR(B8/B9,0) | C22: Average times each person saw you. Above ~3.5, fatigue starts | E22: Less: payment processing | F22: =-IFERROR(B15*F9,0) | G22: Gateway fees
A23: Click → Landing page % | B23: =IFERROR(B11/B10,0) | C23: Site speed and load quality. Below 60% is a technical problem | E23: Less: returns & refunds | F23: =-IFERROR(B15*F10,0) | G23: Money you sent back
A24: Landing page → Add to cart % | B24: =IFERROR(B12/B11,0) | C24: Product page: offer, price, imagery | E24: Less: other variable costs | F24: =-IFERROR(B14*F11,0) | G24: Anything order-linked
A25: Add to cart → Checkout % | B25: =IFERROR(B13/B12,0) | C25: Shipping cost and surprise fees show up here | E25: =Contribution margin | F25: =SUM(F19:F24) | G25: What's left to pay for ads, overhead and profit
A26: Checkout → Purchase % | B26: =IFERROR(B14/B13,0) | C26: Payment options and trust signals | E26: Contribution margin % | F26: =IFERROR(F25/F19,0) | G26: The single most important input in this whole file
A27: Click → Purchase CVR % | B27: =IFERROR(B14/B10,0) | C27: End-to-end site conversion on paid traffic | E27: Contribution per order | F27: =IFERROR(F25/B14,0) | G27: Profit per order before ad spend
A28: Cost per add to cart | B28: =IFERROR(B7/B12,0) | C28: Cheap intent. Good for judging creative before purchase data settles | E28: BREAKEVEN ROAS | F28: =IFERROR(1/F26,0) | G28: Below this, every sale loses money. Report this next to ROAS, always
A29: Cost per checkout | B29: =IFERROR(B7/B13,0) | C29: Mid-funnel cost | E29: Target ROAS for your margin goal | F29: =IFERROR(1/(F26-F14),0) | G29: The ROAS you must hit to deliver the client's target profit
A30: Cost per purchase (CPA) | B30: =IFERROR(B7/B14,0) | C30: The number clients fixate on. Always show AOV beside it | E30: ROAS achieved | F30: =IFERROR(B15/B7,0) | G30: What you actually delivered
A31: AOV (average order value) | B31: =IFERROR(B15/B14,0) | C31: Revenue ÷ orders. Rising AOV can rescue a falling CVR | E31: =Profit after ad spend | F31: =F25-B7 | G31: Contribution minus media. The line that matters
A32: ROAS | B32: =IFERROR(B15/B7,0) | C32: Revenue ÷ ad spend. Meaningless without breakeven ROAS | E32: POAS (profit on ad spend) | F32: =IFERROR(F31/B7,0) | G32: Profit per 1 unit of ad spend. The margin-aware sibling of ROAS
A33: Revenue per 1,000 impressions | B33: =IFERROR(B15/B8*1000,0) | C33: Media efficiency end to end — the cleanest single measure | E33: Profit after fixed costs | F33: =F31-F12 | G33: Ad-funded contribution minus overhead
A34: Spend as % of revenue | B34: =IFERROR(B7/B15,0) | C34: Share of revenue going back into ads | E34: Net profit after agency fee | F34: =F33-F13 | G34: The bottom line the client sees
E35: MER (blended ROAS) | F35: =IFERROR(F15/B7,0) | G35: All revenue ÷ ad spend. Blank if you didn't enter blended revenue
A37: 5 · THE VERDICT — plain English, updates live. Paste straight into a client email.
A38: =IF(F19<=0,"⚠ Add your business inputs first (section 2) — the verdict needs them.","Profitability: after ad spend the account kept "&ROUND(F31,0)&" EGP. Breakeven ROAS is "&ROUND(F28,2)&"x and you delivered "&ROUND(F30,2)&"x — "&IF(F30>=F28,"you are trading above breakeven, so the account is making money on media.","you are trading BELOW breakeven: at this margin, this spend is not paying for itself."))
A39: ="Headroom: at a "&ROUND(F26*100,1)&"% contribution margin you can carry up to "&ROUND(B15*F26,0)&" EGP of ad spend before ads stop paying for themselves. You spent "&ROUND(B7,0)&" EGP, so there is "&ROUND(B15*F26-B7,0)&" EGP of room at today's efficiency."
A40: ="Efficiency: every 1,000 impressions cost "&ROUND(B19,2)&" EGP and returned "&ROUND(B33,2)&" EGP of revenue ("&ROUND(IFERROR(B33/B19,0),2)&"x). You paid "&ROUND(B20,2)&" EGP per link click and that click converted to a purchase "&ROUND(B27*100,2)&"% of the time."
A41: ="Tightest bottleneck: "&IF(AND(B23<=B24,B23<=B25,B23<=B26),"click → landing page ("&ROUND(B23*100,1)&"%) — this is usually a page-speed or tracking problem, not a media problem.",IF(AND(B24<=B25,B24<=B26),"landing page → add to cart ("&ROUND(B24*100,1)&"%) — the product page is not persuading. Offer, price, imagery, reviews.",IF(B25<=B26,"add to cart → checkout ("&ROUND(B25*100,1)&"%) — something is being added at checkout: shipping cost, fees, or forced account creation.","checkout → purchase ("&ROUND(B26*100,1)&"%) — payment options or trust signals are costing you completed orders.")))&" Every other step is above it, so fix this one first."
A42: ="Volume: you bought "&ROUND(B8,0)&" impressions and reached "&ROUND(B9,0)&" people, so the average person saw you "&ROUND(B22,2)&" times. "&IF(B22>3.5,"That is high — refresh creative before you add budget, or you will keep paying more for the same eyeballs.",IF(B22<1.6,"That is very low — you are under-spending into a proven audience. There is budget headroom here.","That is a healthy range, so there is room to add budget before creative fatigue bites."))
A44: 6 · SANITY CHECKS — run these before you send anything to a client
...

Sheet Profit Bridge
A1: Profit Bridge
A2: Where every unit of revenue actually goes — and what ROAS you need to make money.
A3: All amounts in EGP. Change the currency label on 'Start Here' after you copy this file.
A5: REVENUE → PROFIT, WATERFALL
A6: Step | B6: Per order | C6: This period | D6: % of revenue | E6: Share of revenue
A7: Revenue | B7: =IFERROR(=Calculator!F19/Calculator!$B$14,0) | C7: =Calculator!F19 | D7: =IFERROR(=Calculator!F19/Calculator!$F$19,0) | E7: =REPT("█",MAX(0,ROUND(18*IFERROR(=Calculator!F19/Calculator!$F$19,0),0)))
A8: Less: COGS | B8: =IFERROR(=Calculator!F20/Calculator!$B$14,0) | C8: =Calculator!F20 | D8: =IFERROR(=Calculator!F20/Calculator!$F$19,0) | E8: =REPT("█",MAX(0,ROUND(18*IFERROR(=Calculator!F20/Calculator!$F$19,0),0)))
A9: Less: shipping & fulfilment | B9: =IFERROR(=Calculator!F21/Calculator!$B$14,0) | C9: =Calculator!F21 | D9: =IFERROR(=Calculator!F21/Calculator!$F$19,0) | E9: =REPT("█",MAX(0,ROUND(18*IFERROR(=Calculator!F21/Calculator!$F$19,0),0)))
A10: Less: payment processing | B10: =IFERROR(=Calculator!F22/Calculator!$B$14,0) | C10: =Calculator!F22 | D10: =IFERROR(=Calculator!F22/Calculator!$F$19,0) | E10: =REPT("█",MAX(0,ROUND(18*IFERROR(=Calculator!F22/Calculator!$F$19,0),0)))
A11: Less: returns & refunds | B11: =IFERROR(=Calculator!F23/Calculator!$B$14,0) | C11: =Calculator!F23 | D11: =IFERROR(=Calculator!F23/Calculator!$F$19,0) | E11: =REPT("█",MAX(0,ROUND(18*IFERROR(=Calculator!F23/Calculator!$F$19,0),0)))
A12: Less: other variable costs | B12: =IFERROR(=Calculator!F24/Calculator!$B$14,0) | C12: =Calculator!F24 | D12: =IFERROR(=Calculator!F24/Calculator!$F$19,0) | E12: =REPT("█",MAX(0,ROUND(18*IFERROR(=Calculator!F24/Calculator!$F$19,0),0)))
A13: =Contribution margin | B13: =IFERROR(=Calculator!F25/Calculator!$B$14,0) | C13: =Calculator!F25 | D13: =IFERROR(=Calculator!F25/Calculator!$F$19,0) | E13: =REPT("█",MAX(0,ROUND(18*IFERROR(=Calculator!F25/Calculator!$F$19,0),0)))
A14: Less: ad spend | B14: =IFERROR(=-Calculator!B7/Calculator!$B$14,0) | C14: =-Calculator!B7 | D14: =IFERROR(=-Calculator!B7/Calculator!$F$19,0) | E14: =REPT("█",MAX(0,ROUND(18*IFERROR(=-Calculator!B7/Calculator!$F$19,0),0)))
A15: =Profit after ad spend | B15: =IFERROR(=Calculator!F31/Calculator!$B$14,0) | C15: =Calculator!F31 | D15: =IFERROR(=Calculator!F31/Calculator!$F$19,0) | E15: =REPT("█",MAX(0,ROUND(18*IFERROR(=Calculator!F31/Calculator!$F$19,0),0)))
A16: Less: fixed costs | B16: =IFERROR(=-Calculator!F12/Calculator!$B$14,0) | C16: =-Calculator!F12 | D16: =IFERROR(=-Calculator!F12/Calculator!$F$19,0) | E16: =REPT("█",MAX(0,ROUND(18*IFERROR(=-Calculator!F12/Calculator!$F$19,0),0)))
A17: Less: agency fee | B17: =IFERROR(=-Calculator!F13/Calculator!$B$14,0) | C17: =-Calculator!F13 | D17: =IFERROR(=-Calculator!F13/Calculator!$F$19,0) | E17: =REPT("█",MAX(0,ROUND(18*IFERROR(=-Calculator!F13/Calculator!$F$19,0),0)))
A18: =NET PROFIT | B18: =IFERROR(=Calculator!F34/Calculator!$B$14,0) | C18: =Calculator!F34 | D18: =IFERROR(=Calculator!F34/Calculator!$F$19,0) | E18: =REPT("█",MAX(0,ROUND(18*IFERROR(=Calculator!F34/Calculator!$F$19,0),0)))
A21: WHAT ROAS DO YOU ACTUALLY NEED? — sensitivity at your current spend and costs
A22: Same spend, same costs, different ROAS. This is the table that ends the "is 2x good?" argument.
A23: ROAS | B23: Revenue | C23: Contribution margin | D23: Profit after ads | E23: Verdict
A24: 1 | B24: =(Calculator!$B$7*1.0) | C24: =((Calculator!$B$7*1.0)*(1-Calculator!$F$7-Calculator!$F$9-Calculator!$F$10)-((Calculator!$B$7*1.0)/IFERROR(Calculator!$B$31,1))*(Calculator!$F$8+Calculator!$F$11)) | D24: =((Calculator!$B$7*1.0)*(1-Calculator!$F$7-Calculator!$F$9-Calculator!$F$10)-((Calculator!$B$7*1.0)/IFERROR(Calculator!$B$31,1))*(Calculator!$F$8+Calculator!$F$11))-Calculator!$B$7 | E24: =IF(D24<0,"Losing money — below cost",IF(D24<Calculator!$F$12+Calculator!$F$13,"Covers media only","Profitable after all costs"))
A25: 1.25 | B25: =(Calculator!$B$7*1.25) | C25: =((Calculator!$B$7*1.25)*(1-Calculator!$F$7-Calculator!$F$9-Calculator!$F$10)-((Calculator!$B$7*1.25)/IFERROR(Calculator!$B$31,1))*(Calculator!$F$8+Calculator!$F$11)) | D25: =((Calculator!$B$7*1.25)*(1-Calculator!$F$7-Calculator!$F$9-Calculator!$F$10)-((Calculator!$B$7*1.25)/IFERROR(Calculator!$B$31,1))*(Calculator!$F$8+Calculator!$F$11))-Calculator!$B$7 | E25: =IF(D25<0,"Losing money — below cost",IF(D25<Calculator!$F$12+Calculator!$F$13,"Covers media only","Profitable after all costs"))
A26: 1.5 | B26: =(Calculator!$B$7*1.5) | C26: =((Calculator!$B$7*1.5)*(1-Calculator!$F$7-Calculator!$F$9-Calculator!$F$10)-((Calculator!$B$7*1.5)/IFERROR(Calculator!$B$31,1))*(Calculator!$F$8+Calculator!$F$11)) | D26: =((Calculator!$B$7*1.5)*(1-Calculator!$F$7-Calculator!$F$9-Calculator!$F$10)-((Calculator!$B$7*1.5)/IFERROR(Calculator!$B$31,1))*(Calculator!$F$8+Calculator!$F$11))-Calculator!$B$7 | E26: =IF(D26<0,"Losing money — below cost",IF(D26<Calculator!$F$12+Calculator!$F$13,"Covers media only","Profitable after all costs"))
A27: 1.75 | B27: =(Calculator!$B$7*1.75) | C27: =((Calculator!$B$7*1.75)*(1-Calculator!$F$7-Calculator!$F$9-Calculator!$F$10)-((Calculator!$B$7*1.75)/IFERROR(Calculator!$B$31,1))*(Calculator!$F$8+Calculator!$F$11)) | D27: =((Calculator!$B$7*1.75)*(1-Calculator!$F$7-Calculator!$F$9-Calculator!$F$10)-((Calculator!$B$7*1.75)/IFERROR(Calculator!$B$31,1))*(Calculator!$F$8+Calculator!$F$11))-Calculator!$B$7 | E27: =IF(D27<0,"Losing money — below cost",IF(D27<Calculator!$F$12+Calculator!$F$13,"Covers media only","Profitable after all costs"))
A28: 2 | B28: =(Calculator!$B$7*2.0) | C28: =((Calculator!$B$7*2.0)*(1-Calculator!$F$7-Calculator!$F$9-Calculator!$F$10)-((Calculator!$B$7*2.0)/IFERROR(Calculator!$B$31,1))*(Calculator!$F$8+Calculator!$F$11)) | D28: =((Calculator!$B$7*2.0)*(1-Calculator!$F$7-Calculator!$F$9-Calculator!$F$10)-((Calculator!$B$7*2.0)/IFERROR(Calculator!$B$31,1))*(Calculator!$F$8+Calculator!$F$11))-Calculator!$B$7 | E28: =IF(D28<0,"Losing money — below cost",IF(D28<Calculator!$F$12+Calculator!$F$13,"Covers media only","Profitable after all costs"))
A29: 2.25 | B29: =(Calculator!$B$7*2.25) | C29: =((Calculator!$B$7*2.25)*(1-Calculator!$F$7-Calculator!$F$9-Calculator!$F$10)-((Calculator!$B$7*2.25)/IFERROR(Calculator!$B$31,1))*(Calculator!$F$8+Calculator!$F$11)) | D29: =((Calculator!$B$7*2.25)*(1-Calculator!$F$7-Calculator!$F$9-Calculator!$F$10)-((Calculator!$B$7*2.25)/IFERROR(Calculator!$B$31,1))*(Calculator!$F$8+Calculator!$F$11))-Calculator!$B$7 | E29: =IF(D29<0,"Losing money — below cost",IF(D29<Calculator!$F$12+Calculator!$F$13,"Covers media only","Profitable after all costs"))
A30: 2.5 | B30: =(Calculator!$B$7*2.5) | C30: =((Calculator!$B$7*2.5)*(1-Calculator!$F$7-Calculator!$F$9-Calculator!$F$10)-((Calculator!$B$7*2.5)/IFERROR(Calculator!$B$31,1))*(Calculator!$F$8+Calculator!$F$11)) | D30: =((Calculator!$B$7*2.5)*(1-Calculator!$F$7-Calculator!$F$9-Calculator!$F$10)-((Calculator!$B$7*2.5)/IFERROR(Calculator!$B$31,1))*(Calculator!$F$8+Calculator!$F$11))-Calculator!$B$7 | E30: =IF(D30<0,"Losing money — below cost",IF(D30<Calculator!$F$12+Calculator!$F$13,"Covers media only","Profitable after all costs"))
A31: 2.75 | B31: =(Calculator!$B$7*2.75) | C31: =((Calculator!$B$7*2.75)*(1-Calculator!$F$7-Calculator!$F$9-Calculator!$F$10)-((Calculator!$B$7*2.75)/IFERROR(Calculator!$B$31,1))*(Calculator!$F$8+Calculator!$F$11)) | D31: =((Calculator!$B$7*2.75)*(1-Calculator!$F$7-Calculator!$F$9-Calculator!$F$10)-((Calculator!$B$7*2.75)/IFERROR(Calculator!$B$31,1))*(Calculator!$F$8+Calculator!$F$11))-Calculator!$B$7 | E31: =IF(D31<0,"Losing money — below cost",IF(D31<Calculator!$F$12+Calculator!$F$13,"Covers media only","Profitable after all costs"))
A32: 3 | B32: =(Calculator!$B$7*3.0) | C32: =((Calculator!$B$7*3.0)*(1-Calculator!$F$7-Calculator!$F$9-Calculator!$F$10)-((Calculator!$B$7*3.0)/IFERROR(Calculator!$B$31,1))*(Calculator!$F$8+Calculator!$F$11)) | D32: =((Calculator!$B$7*3.0)*(1-Calculator!$F$7-Calculator!$F$9-Calculator!$F$10)-((Calculator!$B$7*3.0)/IFERROR(Calculator!$B$31,1))*(Calculator!$F$8+Calculator!$F$11))-Calculator!$B$7 | E32: =IF(D32<0,"Losing money — below cost",IF(D32<Calculator!$F$12+Calculator!$F$13,"Covers media only","Profitable after all costs"))
A33: 3.5 | B33: =(Calculator!$B$7*3.5) | C33: =((Calculator!$B$7*3.5)*(1-Calculator!$F$7-Calculator!$F$9-Calculator!$F$10)-((Calculator!$B$7*3.5)/IFERROR(Calculator!$B$31,1))*(Calculator!$F$8+Calculator!$F$11)) | D33: =((Calculator!$B$7*3.5)*(1-Calculator!$F$7-Calculator!$F$9-Calculator!$F$10)-((Calculator!$B$7*3.5)/IFERROR(Calculator!$B$31,1))*(Calculator!$F$8+Calculator!$F$11))-Calculator!$B$7 | E33: =IF(D33<0,"Losing money — below cost",IF(D33<Calculator!$F$12+Calculator!$F$13,"Covers media only","Profitable after all costs"))
A34: 4 | B34: =(Calculator!$B$7*4.0) | C34: =((Calculator!$B$7*4.0)*(1-Calculator!$F$7-Calculator!$F$9-Calculator!$F$10)-((Calculator!$B$7*4.0)/IFERROR(Calculator!$B$31,1))*(Calculator!$F$8+Calculator!$F$11)) | D34: =((Calculator!$B$7*4.0)*(1-Calculator!$F$7-Calculator!$F$9-Calculator!$F$10)-((Calculator!$B$7*4.0)/IFERROR(Calculator!$B$31,1))*(Calculator!$F$8+Calculator!$F$11))-Calculator!$B$7 | E34: =IF(D34<0,"Losing money — below cost",IF(D34<Calculator!$F$12+Calculator!$F$13,"Covers media only","Profitable after all costs"))
A35: 5 | B35: =(Calculator!$B$7*5.0) | C35: =((Calculator!$B$7*5.0)*(1-Calculator!$F$7-Calculator!$F$9-Calculator!$F$10)-((Calculator!$B$7*5.0)/IFERROR(Calculator!$B$31,1))*(Calculator!$F$8+Calculator!$F$11)) | D35: =((Calculator!$B$7*5.0)*(1-Calculator!$F$7-Calculator!$F$9-Calculator!$F$10)-((Calculator!$B$7*5.0)/IFERROR(Calculator!$B$31,1))*(Calculator!$F$8+Calculator!$F$11))-Calculator!$B$7 | E35: =IF(D35<0,"Losing money — below cost",IF(D35<Calculator!$F$12+Calculator!$F$13,"Covers media only","Profitable after all costs"))
A36: 6 | B36: =(Calculator!$B$7*6.0) | C36: =((Calculator!$B$7*6.0)*(1-Calculator!$F$7-Calculator!$F$9-Calculator!$F$10)-((Calculator!$B$7*6.0)/IFERROR(Calculator!$B$31,1))*(Calculator!$F$8+Calculator!$F$11)) | D36: =((Calculator!$B$7*6.0)*(1-Calculator!$F$7-Calculator!$F$9-Calculator!$F$10)-((Calculator!$B$7*6.0)/IFERROR(Calculator!$B$31,1))*(Calculator!$F$8+Calculator!$F$11))-Calculator!$B$7 | E36: =IF(D36<0,"Losing money — below cost",IF(D36<Calculator!$F$12+Calculator!$F$13,"Covers media only","Profitable after all costs"))
A39: =Calculator!A38

Sheet Period Compare
A1: Period Compare — why did ROAS move?
A2: ROAS = 1,000 × CTR × CVR × AOV ÷ CPM. This tab splits the change in ROAS into those four drivers, so you can name the cause instead of guessing.
A3: All amounts in EGP. Change the currency label on 'Start Here' after you copy this file.
A5: STEP 1 · ENTER TWO PERIODS
A6: Metric | B6: Period A (before) | C6: Period B (after) | D6: Change | E6: Change % | F6: Note
A7: Period label | B7: e.g. Sep 2025 | C7: e.g. Oct 2025
A8: Ad spend
A9: Impressions
A10: Clicks
A11: Purchases
A12: Revenue
A14: STEP 2 · DERIVED DRIVERS
A15: Driver | B15: Period A | C15: Period B | D15: Change | E15: Change % | F15: What it means
A16: CPM | B16: =IFERROR(B8/B9*1000,0) | C16: =IFERROR(C8/C9*1000,0) | D16: =C16-B16 | E16: =IFERROR(C16/B16-1,0) | F16: Cost of attention. Rising = auction pressure or audience saturation
A17: CTR | B17: =IFERROR(B10/B9,0) | C17: =IFERROR(C10/C9,0) | D17: =C17-B17 | E17: =IFERROR(C17/B17-1,0) | F17: Creative hook. Falling = fatigue or the wrong audience
A18: CVR | B18: =IFERROR(B11/B10,0) | C18: =IFERROR(C11/C10,0) | D18: =C18-B18 | E18: =IFERROR(C18/B18-1,0) | F18: Site conversion on paid clicks. Falling = landing page, offer, price or stock
A19: AOV | B19: =IFERROR(B12/B11,0) | C19: =IFERROR(C12/C11,0) | D19: =C19-B19 | E19: =IFERROR(C19/B19-1,0) | F19: Basket size. Falling = discounting, cheaper SKUs, or a bundle ending
A20: ROAS | B20: =IFERROR(B12/B8,0) | C20: =IFERROR(C12/C8,0) | D20: =C20-B20 | E20: =IFERROR(C20/B20-1,0) | F20: The output these four drivers produce
A23: STEP 3 · ATTRIBUTION — each driver's share of the total ROAS move
A24: Sequential substitution: drivers are changed one at a time, in the order below, so the four contributions add up exactly to the total change in ROAS. Order affects the split between correlated drivers, so read the ranking, not the third decimal.
A25: Driver | C25: % of total move | D25: Direction / what it means
A26: CTR (creative hook) | B26: =I26-H26 | C26: =IFERROR(B26/$C$20-$B$20,0) | D26: =IF(B26>0,"Helped","Hurt") | E26: Your creative pulled a different rate of clicks from the same impressions. | H26: =IFERROR(1000*B17*B18*B19/B16,0) | I26: =IFERROR(1000*C17*B18*B19/B16,0)
A27: CVR (site conversion) | B27: =I27-H27 | C27: =IFERROR(B27/$C$20-$B$20,0) | D27: =IF(B27>0,"Helped","Hurt") | E27: The same clicks converted to orders at a different rate. | H27: =IFERROR(1000*C17*B18*B19/B16,0) | I27: =IFERROR(1000*C17*C18*B19/B16,0)
A28: AOV (basket size) | B28: =I28-H28 | C28: =IFERROR(B28/$C$20-$B$20,0) | D28: =IF(B28>0,"Helped","Hurt") | E28: The average order value moved. | H28: =IFERROR(1000*C17*C18*B19/B16,0) | I28: =IFERROR(1000*C17*C18*C19/B16,0)
A29: CPM (cost of attention) | B29: =I29-H29 | C29: =IFERROR(B29/$C$20-$B$20,0) | D29: =IF(B29>0,"Helped","Hurt") | E29: What you paid for impressions changed. | H29: =IFERROR(1000*C17*C18*C19/B16,0) | I29: =IFERROR(C20,0)
A31: Total change in ROAS | B31: =SUM(B26:B29) | C31: =IFERROR(SUM(C26:C29),0) | D31: =IF(B31>0,"ROAS improved","ROAS declined") | E31: These four add up to the total change — nothing is left unexplained.
A33: ="ROAS moved from "&ROUND(B20,2)&"x to "&ROUND(C20,2)&"x. The single biggest driver was "&IF(AND(ABS(B26)>=ABS(B27),ABS(B26)>=ABS(B28),ABS(B26)>=ABS(B29)),"CTR — creative response",IF(AND(ABS(B27)>=ABS(B28),ABS(B27)>=ABS(B29)),"CVR — how the site converted paid clicks",IF(ABS(B28)>=ABS(B29),"AOV — basket size","CPM — the cost of attention")))&" (worth "&ROUND(MAX(ABS(B26),ABS(B27),ABS(B28),ABS(B29))*IF(OR(B26<0,B27<0,B28<0,B29<0),-1,1),2)&" ROAS points). Lead your client update with that, not with the headline number."
A36: How to read this
A37: If CPM rose and it was the only driver, that is a market conversation: you are paying more for the same attention, and the fix is creative, audience or offer — not 'turning things off'. If CVR or AOV moved, that is a business conversation: the site, the price, the stock. Naming which of the two you are in is what separates a report from an excuse.

Sheet Benchmarks
A1: Benchmarks
A2: Editable thresholds. The status column on every report reads from here.
A3: All amounts in EGP. Change the currency label on 'Start Here' after you copy this file.
A4: ⚠ Read this first: | B4: The numbers below are starting points so the status column works on day one — they are not industry truth. Replace them with your own trailing 90-day average per account as soon as you have it. Your own history is the only benchmark that pays rent.
A6: Metric | B6: Your value | C6: Weak | D6: Watch | E6: Target | F6: Strong | G6: Status | H6: If you're below target, look here first
A7: CPM | B7: =Calculator!$B$19 | C7: 190 | D7: 140 | E7: 110 | F7: 80 | G7: =IF($B7=0,"—",IF($B7<=F7,"Strong",IF($B7<=E7,"Target",IF($B7<=D7,"Watch","Weak")))) | H7: Auction pressure, audience saturation, or a broad-targeting test diluting the mix.
A8: CPC | B8: =Calculator!$B$20 | C8: 14 | D8: 9 | E8: 6 | F8: 3.5 | G8: =IF($B8=0,"—",IF($B8<=F8,"Strong",IF($B8<=E8,"Target",IF($B8<=D8,"Watch","Weak")))) | H8: Mostly CPM plus CTR. If CPC is high but CTR is fine, look at placement and audience.
A9: CTR | B9: =Calculator!$B$21 | C9: 0.008 | D9: 0.012 | E9: 0.018 | F9: 0.028 | G9: =IF($B9=0,"—",IF($B9>=F9,"Strong",IF($B9>=E9,"Target",IF($B9>=D9,"Watch","Weak")))) | H9: Creative hook. First 3 seconds of video, first line of primary text.
A10: Click → Landing page % | B10: =Calculator!$B$23 | C10: 0.45 | D10: 0.6 | E10: 0.72 | F10: 0.85 | G10: =IF($B10=0,"—",IF($B10>=F10,"Strong",IF($B10>=E10,"Target",IF($B10>=D10,"Watch","Weak")))) | H10: Page speed and mobile load. This is a technical problem, not a media one.
A11: Landing page → ATC % | B11: =Calculator!$B$24 | C11: 0.03 | D11: 0.055 | E11: 0.08 | F11: 0.13 | G11: =IF($B11=0,"—",IF($B11>=F11,"Strong",IF($B11>=E11,"Target",IF($B11>=D11,"Watch","Weak")))) | H11: Product page: price positioning, imagery, reviews, delivery promise.
A12: ATC → Checkout % | B12: =Calculator!$B$25 | C12: 0.18 | D12: 0.3 | E12: 0.45 | F12: 0.6 | G12: =IF($B12=0,"—",IF($B12>=F12,"Strong",IF($B12>=E12,"Target",IF($B12>=D12,"Watch","Weak")))) | H12: Shipping cost, surprise fees, forced account creation.
A13: Checkout → Purchase % | B13: =Calculator!$B$26 | C13: 0.35 | D13: 0.5 | E13: 0.65 | F13: 0.78 | G13: =IF($B13=0,"—",IF($B13>=F13,"Strong",IF($B13>=E13,"Target",IF($B13>=D13,"Watch","Weak")))) | H13: Payment methods, COD availability, trust badges, retargeting coverage.
A14: Click → Purchase CVR % | B14: =Calculator!$B$27 | C14: 0.008 | D14: 0.015 | E14: 0.025 | F14: 0.04 | G14: =IF($B14=0,"—",IF($B14>=F14,"Strong",IF($B14>=E14,"Target",IF($B14>=D14,"Watch","Weak")))) | H14: The end-to-end site rate on paid clicks. Compare month to month, not to strangers.
A15: Frequency | B15: =Calculator!$B$22 | C15: 5 | D15: 3.5 | E15: 2.4 | F15: 1.5 | G15: =IF($B15=0,"—",IF($B15<=F15,"Strong",IF($B15<=E15,"Target",IF($B15<=D15,"Watch","Weak")))) | H15: Creative fatigue. Above target, refresh before you scale.
A16: AOV | B16: =Calculator!$B$31 | C16: 0 | D16: 0 | E16: 0 | F16: 0 | G16: =IF($B16=0,"—",IF($B16>=F16,"Strong",IF($B16>=E16,"Target",IF($B16>=D16,"Watch","Weak")))) | H16: REPLACE these four cells with this client's real AOV range — it is account-specific.
A17: Revenue per 1,000 impressions | B17: =Calculator!$B$33 | C17: 0 | D17: 0 | E17: 0 | F17: 0 | G17: =IF($B17=0,"—",IF($B17>=F17,"Strong",IF($B17>=E17,"Target",IF($B17>=D17,"Watch","Weak")))) | H17: REPLACE. The cleanest single end-to-end measure of media efficiency.
A18: ROAS | B18: =Calculator!$B$32 | C18: 0 | D18: 0 | E18: 0 | F18: 0 | G18: =IF($B18=0,"—",IF($B18>=F18,"Strong",IF($B18>=E18,"Target",IF($B18>=D18,"Watch","Weak")))) | H18: REPLACE with realistic tiers for this account. Never set a target below breakeven ROAS.
A19: Breakeven ROAS | B19: =Calculator!$F$28 | C19: 0 | D19: 0 | E19: 0 | F19: 0 | G19: =IF($B19=0,"—",IF($B19<=F19,"Strong",IF($B19<=E19,"Target",IF($B19<=D19,"Watch","Weak")))) | H19: This one is calculated from the client's own margin — do not overwrite it.
A20: POAS (profit on ad spend) | B20: =Calculator!$F$32 | C20: 0 | D20: 0 | E20: 0 | F20: 0 | G20: =IF($B20=0,"—",IF($B20>=F20,"Strong",IF($B20>=E20,"Target",IF($B20>=D20,"Watch","Weak")))) | H20: Profit per unit of spend. The number to move when ROAS is already acceptable.
A22: How status is decided
A23: Higher is better (CTR, CVR, AOV, ROAS, POAS): Strong ≥ column F, Target ≥ E, Watch ≥ D, below D = Weak.
A24: Lower is better (CPM, CPC, Frequency, Breakeven ROAS): the same logic mirrored.

Sheet Metric Dictionary
A1: Metric Dictionary
A2: One shared definition per metric — for you, the client, and the AI prompts. If a number isn't defined here, don't report it.
A5: Metric | B5: How it is calculated | C5: What it actually tells you | D5: How it is most often misused
A6: Spend | B6: Sum of ad spend for the period | C6: Money out the door on media only — exclude agency fees and tooling. | D6: Bundling management fees into spend, which makes every efficiency metric worse than reality.
A7: Impressions | B7: Counted each time the ad renders | C7: Volume of attention bought. | D7: Using impressions as a success metric on its own. Cheap impressions nobody acts on are not a win.
A8: Reach | B8: Unique people who saw the ad | C8: How many actual humans, deduplicated. | D8: Adding reach across months or platforms. Reach does not sum — deduplicated people overlap.
A9: Frequency | B9: Impressions ÷ Reach | C9: Average number of times each person saw you. | D9: Averaging the daily frequency column. Average the ratio, or use total impressions ÷ total reach.
A10: CPM | B10: Spend ÷ Impressions × 1,000 | C10: What you paid for 1,000 impressions — the price of attention. | D10: Calling a rising CPM your fault. It is often auction-wide. Check CTR and CVR before you blame the account.
A11: CTR | B11: Clicks ÷ Impressions | C11: How well the creative earns a click. | D11: Mixing 'all clicks' with 'link clicks'. Outbound/link clicks only, every time, or the number drifts.
A12: CPC | B12: Spend ÷ Clicks | C12: Cost of a visit to the site. | D12: Optimising CPC in isolation — cheaper clicks from a worse audience convert worse.
A13: Landing page view (LPV) | B13: Page loaded after a click | C13: How many clicks actually arrived on the site. | D13: Ignoring the gap between clicks and LPVs. A large gap is a page-speed problem masquerading as a media problem.
A14: Add to cart (ATC) | B14: Product added to cart | C14: Cheap, early intent signal. | D14: Treating ATC as a proxy for revenue. High ATC with low checkout = shipping cost shock.
A15: Initiate checkout (IC) | B15: Checkout started | C15: The last step before money changes hands. | D15: Assuming IC → Purchase is a media metric. It is almost always a payment or trust issue.
A16: Purchases | B16: Attributed orders in the platform window | C16: Orders the platform takes credit for. | D16: Comparing platforms without matching attribution windows. 7-day-click on Meta vs 7-day on TikTok is fine; 1-day vs 7-day is not.
... A26: Attribution window | B26: The lookback period credited to an ad | C26: How generous the platform is being with its own credit. | D26: Changing the window between months, then presenting the change as performance. Fix the window and note it on the report.
